Workbook
Name employees: Employees!$A$3:$A$19

Sheet 2023 Totals
B3: Employee | C3: CO Leave count | D3: Extra Working days count | E3: Monthly count
B4: =Jan!B6 -> KC Tirkey | C4: =Jan!AH6+Feb!AE6+Mar!AH6+Apr!AG6+May!AH6+Jun!AG6+Jul!AH6+Aug!AH6+Sep!AG6+Oct!AH6+Nov!AG6+Dec!AH6 -> 29 | D4: =Jan!AI6+Feb!AF6+Mar!AI6+Apr!AH6+May!AI6+Jun!AH6+Jul!AI6+Aug!AI6+Sep!AH6+Oct!AI6+Nov!AH6+Dec!AI6 -> 25 | E4: =Jan!AJ6+Feb!AG6+Mar!AJ6+Apr!AI6+May!AJ6+Jun!AI6+Jul!AJ6+Aug!AJ6+Sep!AI6+Oct!AJ6+Nov!AI6+Dec!AJ6 -> 12 | F4: 2023
B5: =Jan!B7 -> GN Madhei | C5: =Jan!AH7+Feb!AE7+Mar!AH7+Apr!AG7+May!AH7+Jun!AG7+Jul!AH7+Aug!AH7+Sep!AG7+Oct!AH7+Nov!AG7+Dec!AH7 -> 54 | D5: =Jan!AI7+Feb!AF7+Mar!AI7+Apr!AH7+May!AI7+Jun!AH7+Jul!AI7+Aug!AI7+Sep!AH7+Oct!AI7+Nov!AH7+Dec!AI7 -> 34 | E5: =Jan!AJ7+Feb!AG7+Mar!AJ7+Apr!AI7+May!AJ7+Jun!AI7+Jul!AJ7+Aug!AJ7+Sep!AI7+Oct!AJ7+Nov!AI7+Dec!AJ7 -> 12
B6: =Jan!B8 -> S Behera | C6: =SUM(Jan!AH8+Feb!AE8+Mar!AH8+Apr!AG8+May!AH8+Jun!AG8) -> 18 | D6: =SUM(Jan!AI8+Feb!AF8+Mar!AI8+Apr!AH8+May!AI8+Jun!AH8) -> 7 | E6: =SUM(Jan!AJ8+Feb!AG8+Mar!AJ8+Apr!AI8+May!AJ8+Jun!AI8) -> 6
B7: =Jan!B9 -> S Lakra | C7: =Jan!AH9+Feb!AE9+Mar!AH9+Apr!AG9+May!AH9+Jun!AG9+Jul!AH8+Aug!AH8+Sep!AG8+Oct!AH8+Nov!AG8+Dec!AH8 -> 32 | D7: =Jan!AI9+Feb!AF9+Mar!AI9+Apr!AH9+May!AI9+Jun!AH9+Jul!AI8+Aug!AI8+Sep!AH8+Oct!AI8+Nov!AH8+Dec!AI8 -> 18 | E7: =Jan!AJ9+Feb!AG9+Mar!AJ9+Apr!AI9+May!AJ9+Jun!AI9+Jul!AJ8+Aug!AJ8+Sep!AI8+Oct!AJ8+Nov!AI8+Dec!AJ8 -> 12
B8: =Jan!B10 -> SK Maharana | C8: =Jan!AH10+Feb!AE10+Mar!AH10+Apr!AG10+May!AH10+Jun!AG10+Jul!AH9+Aug!AH9+Sep!AG9+Oct!AH9+Nov!AG9+Dec!AH9 -> 33 | D8: =Jan!AI10+Feb!AF10+Mar!AI10+Apr!AH10+May!AI10+Jun!AH10+Jul!AI9+Aug!AI9+Sep!AH9+Oct!AI9+Nov!AH9+Dec!AI9 -> 14 | E8: =Jan!AJ10+Feb!AG10+Mar!AJ10+Apr!AI10+May!AJ10+Jun!AI10+Jul!AJ9+Aug!AJ9+Sep!AI9+Oct!AJ9+Nov!AI9+Dec!AJ9 -> 12
B9: =Jan!B11 -> PK Sahoo Sr | C9: =Jan!AH11+Feb!AE11+Mar!AH11+Apr!AG11+May!AH11+Jun!AG11+Jul!AH10+Aug!AH10+Sep!AG10+Oct!AH10+Nov!AG10+Dec!AH10 -> 36 | D9: =Jan!AI11+Feb!AF11+Mar!AI11+Apr!AH11+May!AI11+Jun!AH11+Jul!AI10+Aug!AI10+Sep!AH10+Oct!AI10+Nov!AH10+Dec!AI10 -> 19 | E9: =Jan!AJ11+Feb!AG11+Mar!AJ11+Apr!AI11+May!AJ11+Jun!AI11+Jul!AJ10+Aug!AJ10+Sep!AI10+Oct!AJ10+Nov!AI10+Dec!AJ10 -> 12
B10: =Jan!B12 -> RK Singh | C10: =(Jan!AH12+Feb!AE12+Mar!AH12+Apr!AG12+May!AH12+Jun!AG12+Jul!AH11+Aug!AH11+Sep!AG11+Oct!AH11+Nov!AG11+Dec!AH11) -> 16 | D10: =SUM(Jan!AI12+Feb!AF12+Mar!AI12+Apr!AH12+May!AI12+Jun!AH12+Jul!AI12) -> 4 | E10: =SUM(Jan!AJ12+Feb!AG12+Mar!AJ12+Apr!AI12+May!AJ12+Jun!AI12+Jul!AJ12+Aug!AJ12+Sep!AI12+Oct!AJ12+Nov!AI12+Dec!AJ12) -> 12
B11: =Jan!B13 -> PN Rout | C11: =Jan!AH13+Feb!AE13+Mar!AH13 -> 8 | D11: =Jan!AI13+Feb!AF13+Mar!AI13 -> 3 | E11: =Jan!AJ13+Feb!AG13+Mar!AJ13 -> 3
B12: =Jan!B14 -> PK Sahoo Jr | C12: =Jan!AH14+Feb!AE14+Mar!AH14+Apr!AG14+May!AH14+Jun!AG14+Jul!AH14+Aug!AH14+Sep!AG14+Oct!AH14+Nov!AG14+Dec!AH14 -> 30 | D12: =Jan!AI14+Feb!AF14+Mar!AI14+Apr!AH14+May!AI14+Jun!AH14+Jul!AI14+Aug!AI14+Sep!AH14+Oct!AI14+Nov!AH14+Dec!AI14 -> 14 | E12: =Jan!AJ14+Feb!AG14+Mar!AJ14+Apr!AI14+May!AJ14+Jun!AI14+Jul!AJ14+Aug!AJ14+Sep!AI14+Oct!AJ14+Nov!AI14+Dec!AJ14 -> 12
B13: =Jan!B15 -> D Pangi | C13: =SUM(Jan!AH15+Feb!AE15+Mar!AH15+Apr!AG15+May!AH15+Jun!AG15+Jul!AH15+Aug!AH15+Sep!AG15+Oct!AH15+Nov!AG15+Dec!AH15) -> 3 | D13: =SUM(Jan!AI15+Feb!AF15+Mar!AI15+Apr!AH15+May!AI15+Jun!AH15+Jul!AI15+Aug!AI15+Sep!AH15+Oct!AI15+Nov!AH15+Dec!AI15) -> 0 | E13: =SUM(Jan!AJ15+Feb!AG15+Mar!AJ15+Apr!AI15+May!AJ15+Jun!AI15+Jul!AJ15+Aug!AJ15+Sep!AI15+Oct!AJ15+Nov!AI15+Dec!AJ15) -> 12
A14: Apr'23 | B14: =Jan!B16 -> M Bishi | C14: =Apr!AG13+May!AH13+Jun!AG13+Jul!AH12+Aug!AH12+Sep!AG12+Oct!AH12+Nov!AG12+Dec!AH12 -> 16 | D14: =Apr!AH13+May!AI13+Jun!AH13+Jul!AI12+Aug!AI12+Sep!AH12+Oct!AI12+Nov!AH12+Dec!AI12 -> 10 | E14: =Apr!AI13+May!AJ13+Jun!AI13+Jul!AJ12+Aug!AJ12+Sep!AI12+Oct!AJ12+Nov!AI12+Dec!AJ12 -> 9
A15: July'23 | B15: =Jan!B17 -> S C Behera | C15: =Jul!AH13+Aug!AH13+Sep!AG13+Oct!AH13+Nov!AG13+Dec!AH13 -> 16 | D15: =Jul!AI13+Aug!AI13+Sep!AH13+Oct!AI13+Nov!AH13+Dec!AI13 -> 0 | E15: =Jul!AJ13+Aug!AJ13+Sep!AI13+Oct!AJ13+Nov!AI13+Dec!AJ13 -> 6
B16: =Jan!B18 -> S K Sahoo
B17: =Jan!B19 -> A K Dalai
B18: =Jan!B20 -> M C Tudu
B19: TOTAL | C19: =SUM(C4:C18) -> 291 | D19: =SUM(D4:D18) -> 148 | E19: =SUM(E4:E18) -> 120
B20: Employee | C20: CO Leave count | D20: Extra Working days count | E20: Monthly count
B21: =B4 -> KC Tirkey | C21: ='Jan24'!AH6+'FEB24'!AH6+'mAR24'!AH6+'Apr24'!AH6+'mAY24'!AH6+'jUN24'!AH6+jULY24!AH6+'aUG''24'!AH6+'Sep''24'!AH6 -> 45 | D21: ='Jan24'!AI6+'FEB24'!AI6+'mAR24'!AI6+'Apr24'!AI6+'mAY24'!AI6+'jUN24'!AI6+jULY24!AI6+'aUG''24'!AI6+'Sep''24'!AI6 -> 34 | E21: ='Jan24'!AJ6+'FEB24'!AJ6+'mAR24'!AJ6+'Apr24'!AJ6+'mAY24'!AJ6+'jUN24'!AJ6+jULY24!AJ6+'aUG''24'!AJ6+'Sep''24'!AJ6 -> 9 | F21: 2024
B22: =B5 -> GN Madhei | C22: ='Jan24'!AH7+'FEB24'!AH7+'mAR24'!AH7+'Apr24'!AH7+'mAY24'!AH7+'jUN24'!AH7+jULY24!AH7+'aUG''24'!AH7+'Sep''24'!AH7+'oct''24'!AH7+'nov''24'!AH7+'dec''24'!AH7 -> 50 | D22: ='Jan24'!AI7+'FEB24'!AI7+'mAR24'!AI7+'Apr24'!AI7+'mAY24'!AI7+'jUN24'!AI7+jULY24!AI7+'aUG''24'!AI7+'Sep''24'!AI7+'oct''24'!AI7+'nov''24'!AI7+'dec''24'!AI7 -> 29 | E22: ='Jan24'!AJ7+'FEB24'!AJ7+'mAR24'!AJ7+'Apr24'!AJ7+'mAY24'!AJ7+'jUN24'!AJ7+jULY24!AJ7+'aUG''24'!AJ7+'Sep''24'!AJ7+'oct''24'!AJ7+'nov''24'!AJ7+'dec''24'!AJ7 -> 12
A23: Jan'24 | B23: =B16 -> S K Sahoo | C23: ='Jan24'!AH8+'FEB24'!AH8+'mAR24'!AH8+'Apr24'!AH8+'mAY24'!AH8+'jUN24'!AH8+jULY24!AH8+'aUG''24'!AH8+'Sep''24'!AH8+'oct''24'!AH8+'nov''24'!AH8+'dec''24'!AH8 -> 38 | D23: ='Jan24'!AI8+'FEB24'!AI8+'mAR24'!AI8+'Apr24'!AI8+'mAY24'!AI8+'jUN24'!AI8+jULY24!AI8+'aUG''24'!AI8+'Sep''24'!AI8+'oct''24'!AI8+'nov''24'!AI8+'dec''24'!AI8 -> 28 | E23: ='Jan24'!AJ8+'FEB24'!AJ8+'mAR24'!AJ8+'Apr24'!AJ8+'mAY24'!AJ8+'jUN24'!AJ8+jULY24!AJ8+'aUG''24'!AJ8+'Sep''24'!AJ8+'oct''24'!AJ8+'nov''24'!AJ8+'dec''24'!AJ8 -> 12
B24: =B7 -> S Lakra | C24: ='Jan24'!AH9+'FEB24'!AH9+'mAR24'!AH9+'Apr24'!AH9+'mAY24'!AH9+'jUN24'!AH9 -> 23 | D24: ='Jan24'!AI9+'FEB24'!AI9+'mAR24'!AI9+'Apr24'!AI9+'mAY24'!AI9+'jUN24'!AI9 -> 19 | E24: ='Jan24'!AJ9+'FEB24'!AJ9+'mAR24'!AJ9+'Apr24'!AJ9+'mAY24'!AJ9+'jUN24'!AJ9 -> 6
B25: =B8 -> SK Maharana | C25: ='Jan24'!AH10+'FEB24'!AH10+'mAR24'!AH10+'Apr24'!AH10+'mAY24'!AH10+'jUN24'!AH10+jULY24!AH9+'aUG''24'!AH9+'Sep''24'!AH9+'oct''24'!AH9+'nov''24'!AH9+'dec''24'!AH9 -> 20 | D25: ='Jan24'!AI10+'FEB24'!AI10+'mAR24'!AI10+'Apr24'!AI10+'mAY24'!AI10+'jUN24'!AI10+jULY24!AI9+'aUG''24'!AI9+'Sep''24'!AI9+'oct''24'!AI9+'nov''24'!AI9+'dec''24'!AI9 -> 11 | E25: ='Jan24'!AJ10+'FEB24'!AJ10+'mAR24'!AJ10+'Apr24'!AJ10+'mAY24'!AJ10+'jUN24'!AJ10+jULY24!AJ9+'aUG''24'!AJ9+'Sep''24'!AJ9+'oct''24'!AJ9+'nov''24'!AJ9+'dec''24'!AJ9 -> 12
A26: Apr'24 | B26: =B17 -> A K Dalai | C26: ='Apr24'!AH11+'mAY24'!AH11+'jUN24'!AH11+jULY24!AH10+'aUG''24'!AH10+'Sep''24'!AH10+'oct''24'!AH10+'nov''24'!AH10+'dec''24'!AH10 -> 36 | D26: ='Apr24'!AI11+'mAY24'!AI11+'jUN24'!AI11+jULY24!AI10+'aUG''24'!AI10+'Sep''24'!AI10+'oct''24'!AI10+'nov''24'!AI10+'dec''24'!AI10 -> 28 | E26: ='Apr24'!AJ11+'mAY24'!AJ11+'jUN24'!AJ11+jULY24!AJ10+'aUG''24'!AJ10+'Sep''24'!AJ10+'oct''24'!AJ10+'nov''24'!AJ10+'dec''24'!AJ10 -> 9
B27: =B10 -> RK Singh | C27: ='Jan24'!AH11+'FEB24'!AH11+'mAR24'!AH11+'Apr24'!AH12+'mAY24'!AH12+'jUN24'!AH12+jULY24!AH11+'aUG''24'!AH11+'Sep''24'!AH11+'oct''24'!AH11+'nov''24'!AH11+'dec''24'!AH11 -> 15 | D27: ='Jan24'!AI11+'FEB24'!AI11+'mAR24'!AI11+'Apr24'!AI12+'mAY24'!AI12+'jUN24'!AI12+jULY24!AI11+'aUG''24'!AI11+'Sep''24'!AI11+'oct''24'!AI11+'nov''24'!AI11+'dec''24'!AI11 -> 0 | E27: ='Jan24'!AJ11+'FEB24'!AJ11+'mAR24'!AJ11+'Apr24'!AJ12+'mAY24'!AJ12+'jUN24'!AJ12+jULY24!AJ11+'aUG''24'!AJ11+'Sep''24'!AJ11+'oct''24'!AJ11+'nov''24'!AJ11+'dec''24'!AJ11 -> 12
B28: =B12 -> PK Sahoo Jr | C28: ='Jan24'!AH14+'FEB24'!AH14+'mAR24'!AH14 -> 12 | D28: ='Jan24'!AI14+'FEB24'!AI14+'mAR24'!AI14 -> 3 | E28: ='Jan24'!AJ14+'FEB24'!AJ14+'mAR24'!AJ14 -> 3
B29: =B13 -> D Pangi | C29: ='Jan24'!AH15+'FEB24'!AH15+'mAR24'!AH15+'Apr24'!AH15+'mAY24'!AH15+'jUN24'!AH15+jULY24!AH15+'aUG''24'!AH15+'Sep''24'!AH15+'oct''24'!AH15+'nov''24'!AH15+'dec''24'!AH15 -> 7 | D29: ='Jan24'!AI15+'FEB24'!AI15+'mAR24'!AI15+'Apr24'!AI15+'mAY24'!AI15+'jUN24'!AI15+jULY24!AI15+'aUG''24'!AI15+'Sep''24'!AI15+'oct''24'!AI15+'nov''24'!AI15+'dec''24'!AI15 -> 2 | E29: ='Jan24'!AJ15+'FEB24'!AJ15+'mAR24'!AJ15+'Apr24'!AJ15+'mAY24'!AJ15+'jUN24'!AJ15+jULY24!AJ15+'aUG''24'!AJ15+'Sep''24'!AJ15+'oct''24'!AJ15+'nov''24'!AJ15+'dec''24'!AJ15 -> 12
B30: =B14 -> M Bishi | C30: ='Jan24'!AH12+'FEB24'!AH12+'mAR24'!AH12+'Apr24'!AH13+'mAY24'!AH13+'jUN24'!AH13+jULY24!AH12+'aUG''24'!AH12+'Sep''24'!AH12+'oct''24'!AH12+'nov''24'!AH12+'dec''24'!AH12 -> 31 | D30: ='Jan24'!AI12+'FEB24'!AI12+'mAR24'!AI12+'Apr24'!AI13+'mAY24'!AI13+'jUN24'!AI13+jULY24!AI12+'aUG''24'!AI12+'Sep''24'!AI12+'oct''24'!AI12+'nov''24'!AI12+'dec''24'!AI12 -> 14 | E30: ='Jan24'!AJ12+'FEB24'!AJ12+'mAR24'!AJ12+'Apr24'!AJ13+'mAY24'!AJ13+'jUN24'!AJ13+jULY24!AJ12+'aUG''24'!AJ12+'Sep''24'!AJ12+'oct''24'!AJ12+'nov''24'!AJ12+'dec''24'!AJ12 -> 12
B31: =B15 -> S C Behera | C31: ='Jan24'!AH13+'FEB24'!AH13+'mAR24'!AH13+'Apr24'!AH14+'mAY24'!AH14+'jUN24'!AH14+jULY24!AH13+'aUG''24'!AH13+'Sep''24'!AH13+'oct''24'!AH13+'nov''24'!AH13+'dec''24'!AH13 -> 19 | D31: ='Jan24'!AI13+'FEB24'!AI13+'mAR24'!AI13+'Apr24'!AI14+'mAY24'!AI14+'jUN24'!AI14+jULY24!AI13+'aUG''24'!AI13+'Sep''24'!AI13+'oct''24'!AI13+'nov''24'!AI13+'dec''24'!AI13 -> 0 | E31: ='Jan24'!AJ13+'FEB24'!AJ13+'mAR24'!AJ13+'Apr24'!AJ14+'mAY24'!AJ14+'jUN24'!AJ14+jULY24!AJ13+'aUG''24'!AJ13+'Sep''24'!AJ13+'oct''24'!AJ13+'nov''24'!AJ13+'dec''24'!AJ13 -> 12
A32: July'24 | B32: =B18 -> M C Tudu | C32: =jULY24!AH14+'aUG''24'!AH14+'Sep''24'!AH14+'oct''24'!AH14+'nov''24'!AH14+'dec''24'!AH14 -> 12 | D32: =jULY24!AI14+'aUG''24'!AI14+'Sep''24'!AI14+'oct''24'!AI14+'nov''24'!AI14+'dec''24'!AI14 -> 18 | E32: =jULY24!AJ14+'aUG''24'!AJ14+'Sep''24'!AJ14+'oct''24'!AJ14+'nov''24'!AJ14+'dec''24'!AJ14 -> 6
A33: Oct'24 | B33: =Jan!B21 -> S R Mahto | C33: ='oct''24'!AH6+'nov''24'!AH6+'dec''24'!AH6 -> 5 | D33: ='oct''24'!AI6+'nov''24'!AI6+'dec''24'!AI6 -> 11 | E33: ='oct''24'!AJ6+'nov''24'!AJ6+'dec''24'!AJ6 -> 3
B34: Toal | C34: =SUM(C21:C33) -> 313 | D34: =SUM(D21:D33) -> 197 | E34: =SUM(E21:E33) -> 120

Sheet Jan
B1: Attendance Tracker | AE1: January 2023
A4: CF Balance | B4: Name | C4: 1 | D4: 2 | E4: 3 | F4: 4 | G4: 5 | H4: 6 | I4: 7 | J4: 8 | K4: 9 | L4: 10 | M4: 11 | N4: 12 | O4: 13 | P4: 14 | Q4: 15 | R4: 16 | S4: 17 | T4: 18 | U4: 19 | V4: 20 | W4: 21 | X4: 22 | Y4: 23 | Z4: 24 | AA4: 25 | AB4: 26 | AC4: 27 | AD4: 28 | AE4: 29 | AF4: 30 | AG4: 31 | AH4: CO Availed this month | AI4: Extra Working days this month | AJ4: Addition this month
C5: Sun | D5: Mon | E5: Tue | F5: Wed | G5: Thu | H5: Fri | I5: Sat | J5: Sun | K5: Mon | L5: Tue | M5: Wed | N5: Thu | O5: Fri | P5: Sat | Q5: Sun | R5: Mon | S5: Tue | T5: Wed | U5: Thu | V5: Fri | W5: Sat | X5: Sun | Y5: Mon | Z5: Tue | AA5: Wed | AB5: Thu | AC5: Fri | AD5: Sat | AE5: Sun | AF5: Mon | AG5: Tue
A6: -6 | B6: KC Tirkey | AH6: =COUNTIF(C6:AG6, "CO") -> 0 | AI6: =COUNTIF(C6:AG6, "E") -> 0 | AJ6: 1
A7: 34 | B7: GN Madhei | C7: E | K7: CO | L7: CO | U7: E | Z7: E | AH7: =COUNTIF(C7:AG7, "CO") -> 2 | AI7: =COUNTIF(C7:AG7, "E") -> 3 | AJ7: 1
A8: 19 | B8: S Behera | L8: E | M8: E | Y8: E | AH8: =COUNTIF(C8:AG8, "CO") -> 0 | AI8: =COUNTIF(C8:AG8, "E") -> 3 | AJ8: 1
A9: 51 | B9: S Lakra | J9: CO | K9: CO | U9: CO | V9: CO | Y9: CO | AH9: =COUNTIF(C9:AG9, "CO") -> 5 | AI9: =COUNTIF(C9:AG9, "E") -> 0 | AJ9: 1
A10: 48 | B10: SK Maharana | W10: CO | Y10: CO | AH10: =COUNTIF(C10:AG10, "CO") -> 2 | AI10: =COUNTIF(C10:AG10, "E") -> 0 | AJ10: 1
A11: =46+1 -> 47 | B11: PK Sahoo Sr | S11: CO | T11: CO | U11: CO | AH11: =COUNTIF(C11:AG11, "CO") -> 3 | AI11: =COUNTIF(C11:AG11, "E") -> 0 | AJ11: 1
A12: 58 | B12: RK Singh | J12: CO | AH12: =COUNTIF(C12:AG12, "CO") -> 1 | AI12: =COUNTIF(C12:AG12, "E") -> 0 | AJ12: 1
A13: 50 | B13: PN Rout | L13: E | AH13: =COUNTIF(C13:AG13, "CO") -> 0 | AI13: =COUNTIF(C13:AG13, "E") -> 1 | AJ13: 1
A14: 19 | B14: PK Sahoo Jr | S14: E | AE14: CO | AF14: CO | AG14: CO | AH14: =COUNTIF(C14:AG14, "CO") -> 3 | AI14: =COUNTIF(C14:AG14, "E") -> 1 | AJ14: 1
A15: 36 | B15: D Pangi | AH15: =COUNTIF(C15:AG15, "CO") -> 0 | AI15: =COUNTIF(C15:AG15, "E") -> 0 | AJ15: 1
B16: M Bishi
B17: S C Behera
B18: S K Sahoo | C18: Legend: CO- CO AVAILED, E-EXTRA DUTY
B19: A K Dalai
B20: M C Tudu
B21: S R Mahto
B22: S K Nayak
B23: S K Parida

Sheet Feb
B1: Attendance Tracker | AD1: February 2023
A4: CF Balance | B4: Name | C4: 1 | D4: 2 | E4: 3 | F4: 4 | G4: 5 | H4: 6 | I4: 7 | J4: 8 | K4: 9 | L4: 10 | M4: 11 | N4: 12 | O4: 13 | P4: 14 | Q4: 15 | R4: 16 | S4: 17 | T4: 18 | U4: 19 | V4: 20 | W4: 21 | X4: 22 | Y4: 23 | Z4: 24 | AA4: 25 | AB4: 26 | AC4: 27 | AD4: 28 | AE4: CO Availed this month | AF4: Extra Working days this month | AG4: Addition this month
C5: Wed | D5: Thu | E5: Fri | F5: Sat | G5: Sun | H5: Mon | I5: Tue | J5: Wed | K5: Thu | L5: Fri | M5: Sat | N5: Sun | O5: Mon | P5: Tue | Q5: Wed | R5: Thu | S5: Fri | T5: Sat | U5: Sun | V5: Mon | W5: Tue | X5: Wed | Y5: Thu | Z5: Fri | AA5: Sat | AB5: Sun | AC5: Mon | AD5: Tue
A6: =Jan!A6+Jan!AI6+Jan!AJ6-Jan!AH6 -> -5 | B6: =Jan!B6 -> KC Tirkey | AE6: =COUNTIF(C6:AD6, "CO") -> 0 | AF6: =COUNTIF(C6:AD6, "E") -> 0 | AG6: 1
A7: =Jan!A7+Jan!AI7+Jan!AJ7-Jan!AH7 -> 36 | B7: =Jan!B7 -> GN Madhei | E7: CO | F7: CO | K7: CO | L7: CO | Q7: CO | R7: CO | S7: CO | T7: CO | AE7: =COUNTIF(C7:AD7, "CO") -> 8 | AF7: =COUNTIF(C7:AD7, "E") -> 0 | AG7: 1
A8: =Jan!A8+Jan!AI8+Jan!AJ8-Jan!AH8 -> 23 | B8: =Jan!B8 -> S Behera | F8: E | H8: E | I8: E | AE8: =COUNTIF(C8:AD8, "CO") -> 0 | AF8: =COUNTIF(C8:AD8, "E") -> 3 | AG8: 1
A9: =Jan!A9+Jan!AI9+Jan!AJ9-Jan!AH9 -> 47 | B9: =Jan!B9 -> S Lakra | E9: E | N9: E | AE9: =COUNTIF(C9:AD9, "CO") -> 0 | AF9: =COUNTIF(C9:AD9, "E") -> 2 | AG9: 1
A10: =Jan!A10+Jan!AI10+Jan!AJ10-Jan!AH10 -> 47 | B10: =Jan!B10 -> SK Maharana | N10: CO | O10: CO | AE10: =COUNTIF(C10:AD10, "CO") -> 2 | AF10: =COUNTIF(C10:AD10, "E") -> 0 | AG10: 1
A11: =Jan!A11+Jan!AI11+Jan!AJ11-Jan!AH11 -> 45 | B11: =Jan!B11 -> PK Sahoo Sr | N11: E | AE11: =COUNTIF(C11:AD11, "CO") -> 0 | AF11: =COUNTIF(C11:AD11, "E") -> 1 | AG11: 1
A12: =Jan!A12+Jan!AI12+Jan!AJ12-Jan!AH12 -> 58 | B12: =Jan!B12 -> RK Singh | C12: E | AE12: =COUNTIF(C12:AD12, "CO") -> 0 | AF12: =COUNTIF(C12:AD12, "E") -> 1 | AG12: 1
A13: =Jan!A13+Jan!AI13+Jan!AJ13-Jan!AH13 -> 52 | B13: =Jan!B13 -> PN Rout | G13: E | O13: E | AE13: =COUNTIF(C13:AD13, "CO") -> 0 | AF13: =COUNTIF(C13:AD13, "E") -> 2 | AG13: 1
A14: =Jan!A14+Jan!AI14+Jan!AJ14-Jan!AH14 -> 18 | B14: =Jan!B14 -> PK Sahoo Jr | C14: CO | W14: CO | X14: CO | Y14: CO | AA14: CO | AB14: CO | AC14: CO | AE14: =COUNTIF(C14:AD14, "CO") -> 7 | AF14: =COUNTIF(C14:AD14, "E") -> 0 | AG14: 1
A15: =Jan!A15+Jan!AI15+Jan!AJ15-Jan!AH15 -> 37 | B15: =Jan!B15 -> D Pangi | AE15: =COUNTIF(C15:AD15, "CO") -> 0 | AF15: =COUNTIF(C15:AD15, "E") -> 0 | AG15: 1
C18: Legend: CO- CO AVAILED, E-EXTRA DUTY

Sheet Mar
B1: Attendance Tracker | AE1: March 2023
A4: CF Balance | B4: Name | C4: 1 | D4: 2 | E4: 3 | F4: 4 | G4: 5 | H4: 6 | I4: 7 | J4: 8 | K4: 9 | L4: 10 | M4: 11 | N4: 12 | O4: 13 | P4: 14 | Q4: 15 | R4: 16 | S4: 17 | T4: 18 | U4: 19 | V4: 20 | W4: 21 | X4: 22 | Y4: 23 | Z4: 24 | AA4: 25 | AB4: 26 | AC4: 27 | AD4: 28 | AE4: 29 | AF4: 30 | AG4: 31 | AH4: CO Availed this month | AI4: Extra Working days this month | AJ4: Addition this month
C5: Wed | D5: Thu | E5: Fri | F5: Sat | G5: Sun | H5: Mon | I5: Tue | J5: Wed | K5: Thu | L5: Fri | M5: Sat | N5: Sun | O5: Mon | P5: Tue | Q5: Wed | R5: Thu | S5: Fri | T5: Sat | U5: Sun | V5: Mon | W5: Tue | X5: Wed | Y5: Thu | Z5: Fri | AA5: Sat | AB5: Sun | AC5: Mon | AD5: Tue | AE5: Wed | AF5: Thu | AG5: Fri
A6: =Feb!A6+Feb!AF6+Feb!AG6-Feb!AE6 -> -4 | B6: =Jan!B6 -> KC Tirkey | N6: CO | O6: CO | P6: CO | AC6: E | AH6: =COUNTIF(C6:AG6, "CO") -> 3 | AI6: =COUNTIF(C6:AG6, "E") -> 1 | AJ6: 1
A7: =Feb!A7+Feb!AF7+Feb!AG7-Feb!AE7 -> 29 | B7: =Jan!B7 -> GN Madhei | E7: E | P7: E | X7: CO | Y7: CO | Z7: CO | AA7: CO | AC7: CO | AH7: =COUNTIF(C7:AG7, "CO") -> 5 | AI7: =COUNTIF(C7:AG7, "E") -> 2 | AJ7: 1
A8: =Feb!A8+Feb!AF8+Feb!AG8-Feb!AE8 -> 27 | B8: =Jan!B8 -> S Behera | D8: CO | E8: CO | F8: CO | R8: E | AC8: CO | AD8: CO | AE8: CO | AF8: CO | AG8: CO | AH8: =COUNTIF(C8:AG8, "CO") -> 8 | AI8: =COUNTIF(C8:AG8, "E") -> 1 | AJ8: 1
A9: =Feb!A9+Feb!AF9+Feb!AG9-Feb!AE9 -> 50 | B9: =Jan!B9 -> S Lakra | D9: CO | E9: CO | F9: CO | Q9: CO | R9: CO | S9: CO | AH9: =COUNTIF(C9:AG9, "CO") -> 6 | AI9: =COUNTIF(C9:AG9, "E") -> 0 | AJ9: 1
A10: =Feb!A10+Feb!AF10+Feb!AG10-Feb!AE10 -> 46 | B10: =Jan!B10 -> SK Maharana | P10: CO | S10: E | AH10: =COUNTIF(C10:AG10, "CO") -> 1 | AI10: =COUNTIF(C10:AG10, "E") -> 1 | AJ10: 1
A11: =Feb!A11+Feb!AF11+Feb!AG11-Feb!AE11 -> 47 | B11: =Jan!B11 -> PK Sahoo Sr | G11: E | P11: E | Q11: CO | R11: CO | S11: CO | AH11: =COUNTIF(C11:AG11, "CO") -> 3 | AI11: =COUNTIF(C11:AG11, "E") -> 2 | AJ11: 1
A12: =Feb!A12+Feb!AF12+Feb!AG12-Feb!AE12 -> 60 | B12: =Jan!B12 -> RK Singh | AH12: =COUNTIF(C12:AG12, "CO") -> 0 | AI12: =COUNTIF(C12:AG12, "E") -> 0 | AJ12: 1
A13: =Feb!A13+Feb!AF13+Feb!AG13-Feb!AE13 -> 55 | B13: =Jan!B13 -> PN Rout | E13: CO | F13: CO | G13: CO | K13: CO | L13: CO | M13: CO | N13: CO | O13: CO | AH13: =COUNTIF(C13:AG13, "CO") -> 8 | AI13: =COUNTIF(C13:AG13, "E") -> 0 | AJ13: 1
A14: =Feb!A14+Feb!AF14+Feb!AG14-Feb!AE14 -> 12 | B14: =Jan!B14 -> PK Sahoo Jr | F14: E | V14: CO | W14: CO | AB14: CO | AC14: CO | AH14: =COUNTIF(C14:AG14, "CO") -> 4 | AI14: =COUNTIF(C14:AG14, "E") -> 1 | AJ14: 1
A15: =Feb!A15+Feb!AF15+Feb!AG15-Feb!AE15 -> 38 | B15: =Jan!B15 -> D Pangi | AH15: =COUNTIF(C15:AG15, "CO") -> 0 | AI15: =COUNTIF(C15:AG15, "E") -> 0 | AJ15: 1
C17: Legend: CO- CO AVAILED, E-EXTRA DUTY

Sheet Apr
B1: Attendance Tracker | AE1: April 2023
A4: CF Balance | B4: Name | C4: 1 | D4: 2 | E4: 3 | F4: 4 | G4: 5 | H4: 6 | I4: 7 | J4: 8 | K4: 9 | L4: 10 | M4: 11 | N4: 12 | O4: 13 | P4: 14 | Q4: 15 | R4: 16 | S4: 17 | T4: 18 | U4: 19 | V4: 20 | W4: 21 | X4: 22 | Y4: 23 | Z4: 24 | AA4: 25 | AB4: 26 | AC4: 27 | AD4: 28 | AE4: 29 | AF4: 30 | AG4: CO Availed this month | AH4: Extra Working days this month | AI4: Addition this month
C5: Sat | D5: Sun | E5: Mon | F5: Tue | G5: Wed | H5: Thu | I5: Fri | J5: Sat | K5: Sun | L5: Mon | M5: Tue | N5: Wed | O5: Thu | P5: Fri | Q5: Sat | R5: Sun | S5: Mon | T5: Tue | U5: Wed | V5: Thu | W5: Fri | X5: Sat | Y5: Sun | Z5: Mon | AA5: Tue | AB5: Wed | AC5: Thu | AD5: Fri | AE5: Sat | AF5: Sun
A6: =Mar!A6+Mar!AI6+Mar!AJ6-Mar!AH6 -> -5 | B6: =Jan!B6 -> KC Tirkey | F6: E | AC6: CO | AD6: CO | AG6: =COUNTIF(B6:AF6, "CO") -> 2 | AH6: =COUNTIF(B6:AF6, "E") -> 1 | AI6: 1
A7: =Mar!A7+Mar!AI7+Mar!AJ7-Mar!AH7 -> 27 | B7: =Jan!B7 -> GN Madhei | S7: CO | T7: CO | W7: CO | AD7: E | AE7: E | AF7: E | AG7: =COUNTIF(B7:AF7, "CO") -> 3 | AH7: =COUNTIF(B7:AF7, "E") -> 3 | AI7: 1
A8: =Mar!A8+Mar!AI8+Mar!AJ8-Mar!AH8 -> 21 | B8: =Jan!B8 -> S Behera | C8: CO | E8: CO | F8: CO | AG8: =COUNTIF(B8:AF8, "CO") -> 3 | AH8: =COUNTIF(B8:AF8, "E") -> 0 | AI8: 1
A9: =Mar!A9+Mar!AI9+Mar!AJ9-Mar!AH9 -> 45 | B9: =Jan!B9 -> S Lakra | AG9: =COUNTIF(B9:AF9, "CO") -> 0 | AH9: =COUNTIF(B9:AF9, "E") -> 0 | AI9: 1
A10: =Mar!A10+Mar!AI10+Mar!AJ10-Mar!AH10 -> 47 | B10: =Jan!B10 -> SK Maharana | E10: CO | F10: CO | AG10: =COUNTIF(B10:AF10, "CO") -> 2 | AH10: =COUNTIF(B10:AF10, "E") -> 0 | AI10: 1
A11: =Mar!A11+Mar!AI11+Mar!AJ11-Mar!AH11 -> 47 | B11: =Jan!B11 -> PK Sahoo Sr | AD11: CO | AG11: =COUNTIF(B11:AF11, "CO") -> 1 | AH11: =COUNTIF(B11:AF11, "E") -> 0 | AI11: 1
A12: =Mar!A12+Mar!AI12+Mar!AJ12-Mar!AH12 -> 61 | B12: =Jan!B12 -> RK Singh | AG12: =COUNTIF(B12:AF12, "CO") -> 0 | AH12: =COUNTIF(B12:AF12, "E") -> 0 | AI12: 1
A13: 56 | B13: =Jan!B16 -> M Bishi | AG13: =COUNTIF(B13:AF13, "CO") -> 0 | AH13: =COUNTIF(B13:AF13, "E") -> 0 | AI13: 1
A14: =Mar!A14+Mar!AI14+Mar!AJ14-Mar!AH14 -> 10 | B14: =Jan!B14 -> PK Sahoo Jr | AG14: =COUNTIF(B14:AF14, "CO") -> 0 | AH14: =COUNTIF(B14:AF14, "E") -> 0 | AI14: 1
A15: =Mar!A15+Mar!AI15+Mar!AJ15-Mar!AH15 -> 39 | B15: =Jan!B15 -> D Pangi | AE15: CO | AG15: =COUNTIF(B15:AF15, "CO") -> 1 | AH15: =COUNTIF(B15:AF15, "E") -> 0 | AI15: 1
C17: Legend: CO- CO AVAILED, E-EXTRA DUTY
B18: PNRout 48 Nos transferred to Red Area-2

Sheet May
B1: Attendance Tracker | AE1: May 2023
A4: CF Balance | B4: Name | C4: 1 | D4: 2 | E4: 3 | F4: 4 | G4: 5 | H4: 6 | I4: 7 | J4: 8 | K4: 9 | L4: 10 | M4: 11 | N4: 12 | O4: 13 | P4: 14 | Q4: 15 | R4: 16 | S4: 17 | T4: 18 | U4: 19 | V4: 20 | W4: 21 | X4: 22 | Y4: 23 | Z4: 24 | AA4: 25 | AB4: 26 | AC4: 27 | AD4: 28 | AE4: 29 | AF4: 30 | AG4: 31 | AH4: CO Availed this month | AI4: Extra Working days this month | AJ4: Addition this month
C5: Mon | D5: Tue | E5: Wed | F5: Thu | G5: Fri | H5: Sat | I5: Sun | J5: Mon | K5: Tue | L5: Wed | M5: Thu | N5: Fri | O5: Sat | P5: Sun | Q5: Mon | R5: Tue | S5: Wed | T5: Thu | U5: Fri | V5: Sat | W5: Sun | X5: Mon | Y5: Tue | Z5: Wed | AA5: Thu | AB5: Fri | AC5: Sat | AD5: Sun | AE5: Mon | AF5: Tue | AG5: Wed
A6: =Apr!A6+Apr!AH6+Apr!AI6-Apr!AG6 -> -5 | B6: =Jan!B6 -> KC Tirkey | X6: E | AH6: =COUNTIF(C6:AG6, "CO") -> 0 | AI6: =COUNTIF(C6:AG6, "E") -> 1 | AJ6: 1
A7: =Apr!A7+Apr!AH7+Apr!AI7-Apr!AG7 -> 28 | B7: =Jan!B7 -> GN Madhei | N7: E | AH7: =COUNTIF(C7:AG7, "CO") -> 0 | AI7: =COUNTIF(C7:AG7, "E") -> 1 | AJ7: 1
A8: =Apr!A8+Apr!AH8+Apr!AI8-Apr!AG8 -> 19 | B8: =Jan!B8 -> S Behera | Z8: CO | AA8: CO | AB8: CO | AC8: CO | AE8: CO | AF8: CO | AG8: CO | AH8: =COUNTIF(C8:AG8, "CO") -> 7 | AI8: =COUNTIF(C8:AG8, "E") -> 0 | AJ8: 1
A9: =Apr!A9+Apr!AH9+Apr!AI9-Apr!AG9 -> 46 | B9: =Jan!B9 -> S Lakra | M9: CO | N9: CO | O9: CO | P9: CO | AG9: CO | AH9: =COUNTIF(C9:AG9, "CO") -> 5 | AI9: =COUNTIF(C9:AG9, "E") -> 0 | AJ9: 1
A10: =Apr!A10+Apr!AH10+Apr!AI10-Apr!AG10 -> 46 | B10: =Jan!B10 -> SK Maharana | F10: CO | G10: CO | T10: CO | V10: CO | X10: CO | AH10: =COUNTIF(C10:AG10, "CO") -> 5 | AI10: =COUNTIF(C10:AG10, "E") -> 0 | AJ10: 1
A11: =Apr!A11+Apr!AH11+Apr!AI11-Apr!AG11 -> 47 | B11: =Jan!B11 -> PK Sahoo Sr | AH11: =COUNTIF(C11:AG11, "CO") -> 0 | AI11: =COUNTIF(C11:AG11, "E") -> 0 | AJ11: 1
A12: =Apr!A12+Apr!AH12+Apr!AI12-Apr!AG12 -> 62 | B12: =Jan!B12 -> RK Singh | H12: CO | I12: CO | J12: CO | K12: CO | L12: CO | N12: CO | O12: CO | P12: CO | T12: E | AH12: =COUNTIF(C12:AG12, "CO") -> 8 | AI12: =COUNTIF(C12:AG12, "E") -> 1 | AJ12: 1
A13: =Apr!A13+Apr!AH13+Apr!AI13-Apr!AG13 -> 57 | B13: =Jan!B16 -> M Bishi | U13: CO | V13: CO | Y13: CO | Z13: CO | AA13: CO | AB13: CO | AC13: CO | AH13: =COUNTIF(C13:AG13, "CO") -> 7 | AI13: =COUNTIF(C13:AG13, "E") -> 0 | AJ13: 1
A14: =Apr!A14+Apr!AH14+Apr!AI14-Apr!AG14+3 -> 14 | B14: =Jan!B14 -> PK Sahoo Jr | AH14: =COUNTIF(C14:AG14, "CO") -> 0 | AI14: =COUNTIF(C14:AG14, "E") -> 0 | AJ14: 1
A15: =Apr!A15+Apr!AH15+Apr!AI15-Apr!AG15 -> 39 | B15: =Jan!B15 -> D Pangi | AH15: =COUNTIF(C15:AG15, "CO") -> 0 | AI15: =COUNTIF(C15:AG15, "E") -> 0 | AJ15: 1
C17: Legend: CO- CO AVAILED, E-EXTRA DUTY

Sheet Jun
B2: Attendance Tracker | D2: June 2023
A4: CF Balance | B4: Name | C4: 1 | D4: 2 | E4: 3 | F4: 4 | G4: 5 | H4: 6 | I4: 7 | J4: 8 | K4: 9 | L4: 10 | M4: 11 | N4: 12 | O4: 13 | P4: 14 | Q4: 15 | R4: 16 | S4: 17 | T4: 18 | U4: 19 | V4: 20 | W4: 21 | X4: 22 | Y4: 23 | Z4: 24 | AA4: 25 | AB4: 26 | AC4: 27 | AD4: 28 | AE4: 29 | AF4: 30 | AG4: CO Availed this month | AH4: Extra Working days this month | AI4: Addition this month
C5: Thu | D5: Fri | E5: Sat | F5: Sun | G5: Mon | H5: Tue | I5: Wed | J5: Thu | K5: Fri | L5: Sat | M5: Sun | N5: Mon | O5: Tue | P5: Wed | Q5: Thu | R5: Fri | S5: Sat | T5: Sun | U5: Mon | V5: Tue | W5: Wed | X5: Thu | Y5: Fri | Z5: Sat | AA5: Sun | AB5: Mon | AC5: Tue | AD5: Wed | AE5: Thu | AF5: Fri
A6: =May!A6+May!AI6+May!AJ6-May!AH6 -> -3 | B6: =Jan!B6 -> KC Tirkey | C6: CO | D6: CO | F6: CO | G6: CO | T6: E | X6: CO | Y6: CO | AG6: =COUNTIF(B6:AF6, "CO") -> 6 | AH6: =COUNTIF(B6:AF6, "E") -> 1 | AI6: 1
A7: =May!A7+May!AI7+May!AJ7-May!AH7 -> 30 | B7: =Jan!B7 -> GN Madhei | L7: CO | M7: CO | N7: CO | O7: CO | R7: CO | S7: CO | T7: CO | AG7: =COUNTIF(B7:AF7, "CO") -> 7 | AH7: =COUNTIF(B7:AF7, "E") -> 0 | AI7: 1
A8: =May!A8+May!AI8+May!AJ8-May!AH8 -> 13 | B8: =Jan!B8 -> S Behera | AG8: =COUNTIF(B8:AF8, "CO") -> 0 | AH8: =COUNTIF(B8:AF8, "E") -> 0 | AI8: 1
A9: =May!A9+May!AI9+May!AJ9-May!AH9 -> 42 | B9: =Jan!B9 -> S Lakra | C9: CO | G9: E | N9: E | W9: CO | X9: CO | Y9: CO | Z9: CO | AG9: =COUNTIF(B9:AF9, "CO") -> 5 | AH9: =COUNTIF(B9:AF9, "E") -> 2 | AI9: 1
A10: =May!A10+May!AI10+May!AJ10-May!AH10 -> 42 | B10: =Jan!B10 -> SK Maharana | W10: E | AG10: =COUNTIF(B10:AF10, "CO") -> 0 | AH10: =COUNTIF(B10:AF10, "E") -> 1 | AI10: 1
A11: =May!A11+May!AI11+May!AJ11-May!AH11 -> 48 | B11: =Jan!B11 -> PK Sahoo Sr | Y11: CO | Z11: CO | AG11: =COUNTIF(B11:AF11, "CO") -> 2 | AH11: =COUNTIF(B11:AF11, "E") -> 0 | AI11: 1
A12: =May!A12+May!AI12+May!AJ12-May!AH12 -> 56 | B12: =Jan!B12 -> RK Singh | G12: E | AG12: =COUNTIF(B12:AF12, "CO") -> 0 | AH12: =COUNTIF(B12:AF12, "E") -> 1 | AI12: 1
A13: =May!A13+May!AI13+May!AJ13-May!AH13 -> 51 | B13: =Jan!B16 -> M Bishi | Y13: E | AG13: =COUNTIF(B13:AF13, "CO") -> 0 | AH13: =COUNTIF(B13:AF13, "E") -> 1 | AI13: 1
A14: =May!A14+May!AI14+May!AJ14-May!AH14 -> 15 | B14: =Jan!B14 -> PK Sahoo Jr | AG14: =COUNTIF(B14:AF14, "CO") -> 0 | AH14: =COUNTIF(B14:AF14, "E") -> 0 | AI14: 1
A15: =May!A15+May!AI15+May!AJ15-May!AH15 -> 40 | B15: =Jan!B15 -> D Pangi | AC15: CO | AG15: =COUNTIF(B15:AF15, "CO") -> 1 | AH15: =COUNTIF(B15:AF15, "E") -> 0 | AI15: 1
C17: Legend: CO- CO AVAILED, E-EXTRA DUTY

Sheet Jul
A1: Attendance Tracker | H1: July 2023
A4: CF Balance | B4: Name | C4: 1 | D4: 2 | E4: 3 | F4: 4 | G4: 5 | H4: 6 | I4: 7 | J4: 8 | K4: 9 | L4: 10 | M4: 11 | N4: 12 | O4: 13 | P4: 14 | Q4: 15 | R4: 16 | S4: 17 | T4: 18 | U4: 19 | V4: 20 | W4: 21 | X4: 22 | Y4: 23 | Z4: 24 | AA4: 25 | AB4: 26 | AC4: 27 | AD4: 28 | AE4: 29 | AF4: 30 | AG4: 31 | AH4: CO Availed this month | AI4: Extra Working days this month | AJ4: Addition this month
C5: Sat | D5: Sun | E5: Mon | F5: Tue | G5: Wed | H5: Thu | I5: Fri | J5: Sat | K5: Sun | L5: Mon | M5: Tue | N5: Wed | O5: Thu | P5: Fri | Q5: Sat | R5: Sun | S5: Mon | T5: Tue | U5: Wed | V5: Thu | W5: Fri | X5: Sat | Y5: Sun | Z5: Mon | AA5: Tue | AB5: Wed | AC5: Thu | AD5: Fri | AE5: Sat | AF5: Sun | AG5: Mon
A6: =Jun!A6+Jun!AH6+Jun!AI6-Jun!AG6 -> -7 | B6: =Jan!B6 -> KC Tirkey | F6: E | G6: E | M6: CO | N6: CO | P6: CO | AH6: =COUNTIF(C6:AG6, "CO") -> 3 | AI6: =COUNTIF(C6:AG6, "E") -> 2 | AJ6: 1
A7: =Jun!A7+Jun!AH7+Jun!AI7-Jun!AG7 -> 24 | B7: =Jan!B7 -> GN Madhei | T7: E | Y7: CO | Z7: CO | AC7: CO | AD7: CO | AH7: =COUNTIF(C7:AG7, "CO") -> 4 | AI7: =COUNTIF(C7:AG7, "E") -> 1 | AJ7: 1
A8: =Jun!A9+Jun!AH9+Jun!AI9-Jun!AG9 -> 40 | B8: =Jan!B9 -> S Lakra | AB8: E | AF8: E | AH8: =COUNTIF(C8:AG8, "CO") -> 0 | AI8: =COUNTIF(C8:AG8, "E") -> 2 | AJ8: 1
A9: =Jun!A10+Jun!AH10+Jun!AI10-Jun!AG10 -> 44 | B9: =Jan!B10 -> SK Maharana | F9: CO | W9: CO | X9: CO | AA9: E | AH9: =COUNTIF(C9:AG9, "CO") -> 3 | AI9: =COUNTIF(C9:AG9, "E") -> 1 | AJ9: 1
A10: =Jun!A11+Jun!AH11+Jun!AI11-Jun!AG11 -> 47 | B10: =Jan!B11 -> PK Sahoo Sr | C10: CO | D10: CO | E10: CO | F10: CO | G10: CO | H10: CO | J10: CO | K10: CO | AB10: E | AC10: E | AD10: E | AH10: =COUNTIF(C10:AG10, "CO") -> 8 | AI10: =COUNTIF(C10:AG10, "E") -> 3 | AJ10: 1
A11: =Jun!A12+Jun!AH12+Jun!AI12-Jun!AG12 -> 58 | B11: =Jan!B12 -> RK Singh | E11: E | AH11: =COUNTIF(C11:AG11, "CO") -> 0 | AI11: =COUNTIF(C11:AG11, "E") -> 1 | AJ11: 1
A12: =Jun!A13+Jun!AH13+Jun!AI13-Jun!AG13 -> 53 | B12: =Jan!B16 -> M Bishi | K12: E | AH12: =COUNTIF(C12:AG12, "CO") -> 0 | AI12: =COUNTIF(C12:AG12, "E") -> 1 | AJ12: 1
A13: 27 | B13: =Jan!B17 -> S C Behera | P13: CO | Q13: CO | S13: CO | W13: CO | AH13: =COUNTIF(C13:AG13, "CO") -> 4 | AI13: =COUNTIF(C13:AG13, "E") -> 0 | AJ13: 1
A14: =Jun!A14+Jun!AH14+Jun!AI14-Jun!AG14 -> 16 | B14: =Jan!B14 -> PK Sahoo Jr | M14: E | Y14: E | Z14: E | AH14: =COUNTIF(C14:AG14, "CO") -> 0 | AI14: =COUNTIF(C14:AG14, "E") -> 3 | AJ14: 1
A15: =Jun!A15+Jun!AH15+Jun!AI15-Jun!AG15 -> 40 | B15: =Jan!B15 -> D Pangi | I15: CO | AH15: =COUNTIF(C15:AG15, "CO") -> 1 | AI15: =COUNTIF(C15:AG15, "E") -> 0 | AJ15: 1
C16: Legend: CO- CO AVAILED, E-EXTRA DUTY
B18: S Behera 14 Nos transferred to Red Area-2

Sheet Aug
B1: Attendance Tracker | AE1: August 2023
A4: CF Balance | B4: Name | C4: 1 | D4: 2 | E4: 3 | F4: 4 | G4: 5 | H4: 6 | I4: 7 | J4: 8 | K4: 9 | L4: 10 | M4: 11 | N4: 12 | O4: 13 | P4: 14 | Q4: 15 | R4: 16 | S4: 17 | T4: 18 | U4: 19 | V4: 20 | W4: 21 | X4: 22 | Y4: 23 | Z4: 24 | AA4: 25 | AB4: 26 | AC4: 27 | AD4: 28 | AE4: 29 | AF4: 30 | AG4: 31 | AH4: CO Availed this month | AI4: Extra Working days this month | AJ4: Addition this month
C5: Tue | D5: Wed | E5: Thu | F5: Fri | G5: Sat | H5: Sun | I5: Mon | J5: Tue | K5: Wed | L5: Thu | M5: Fri | N5: Sat | O5: Sun | P5: Mon | Q5: Tue | R5: Wed | S5: Thu | T5: Fri | U5: Sat | V5: Sun | W5: Mon | X5: Tue | Y5: Wed | Z5: Thu | AA5: Fri | AB5: Sat | AC5: Sun | AD5: Mon | AE5: Tue | AF5: Wed | AG5: Thu
A6: =Jul!A6+Jul!AI6+Jul!AJ6-Jul!AH6 -> -7 | B6: =Jan!B6 -> KC Tirkey | C6: E | AE6: E | AH6: =COUNTIF(C6:AG6, "CO") -> 0 | AI6: =COUNTIF(C6:AG6, "E") -> 2 | AJ6: 1
A7: =Jul!A7+Jul!AI7+Jul!AJ7-Jul!AH7 -> 22 | B7: =Jan!B7 -> GN Madhei | G7: E | O7: E | U7: CO | V7: CO | W7: CO | X7: CO | AH7: =COUNTIF(C7:AG7, "CO") -> 4 | AI7: =COUNTIF(C7:AG7, "E") -> 2 | AJ7: 1
A8: =Jul!A8+Jul!AI8+Jul!AJ8-Jul!AH8 -> 43 | B8: =Jan!B9 -> S Lakra | AC8: CO | AD8: CO | AF8: CO | AG8: CO | AH8: =COUNTIF(C8:AG8, "CO") -> 4 | AI8: =COUNTIF(C8:AG8, "E") -> 0 | AJ8: 1
A9: =Jul!A9+Jul!AI9+Jul!AJ9-Jul!AH9 -> 43 | B9: =Jan!B10 -> SK Maharana | M9: CO | N9: CO | X9: CO | Y9: CO | Z9: CO | AE9: CO | AF9: E | AG9: E | AH9: =COUNTIF(C9:AG9, "CO") -> 6 | AI9: =COUNTIF(C9:AG9, "E") -> 2 | AJ9: 1
A10: =Jul!A10+Jul!AI10+Jul!AJ10-Jul!AH10 -> 43 | B10: =Jan!B11 -> PK Sahoo Sr | C10: CO | D10: CO | E10: CO | F10: CO | G10: CO | AH10: =COUNTIF(C10:AG10, "CO") -> 5 | AI10: =COUNTIF(C10:AG10, "E") -> 0 | AJ10: 1
A11: =Jul!A11+Jul!AI11+Jul!AJ11-Jul!AH11 -> 60 | B11: =Jan!B12 -> RK Singh | O11: CO | AH11: =COUNTIF(C11:AG11, "CO") -> 1 | AI11: =COUNTIF(C11:AG11, "E") -> 0 | AJ11: 1
A12: =Jul!A12+Jul!AI12+Jul!AJ12-Jul!AH12 -> 55 | B12: =Jan!B16 -> M Bishi | X12: E | AH12: =COUNTIF(C12:AG12, "CO") -> 0 | AI12: =COUNTIF(C12:AG12, "E") -> 1 | AJ12: 1
A13: =Jul!A13+Jul!AI13+Jul!AJ13-Jul!AH13 -> 24 | B13: =Jan!B17 -> S C Behera | AH13: =COUNTIF(C13:AG13, "CO") -> 0 | AI13: =COUNTIF(C13:AG13, "E") -> 0 | AJ13: 1
A14: =Jul!A14+Jul!AI14+Jul!AJ14-Jul!AH14 -> 20 | B14: =Jan!B14 -> PK Sahoo Jr | I14: E | AE14: E | AF14: E | AH14: =COUNTIF(C14:AG14, "CO") -> 0 | AI14: =COUNTIF(C14:AG14, "E") -> 3 | AJ14: 1
A15: =Jul!A15+Jul!AI15+Jul!AJ15-Jul!AH15 -> 40 | B15: =Jan!B15 -> D Pangi | AH15: =COUNTIF(C15:AG15, "CO") -> 0 | AI15: =COUNTIF(C15:AG15, "E") -> 0 | AJ15: 1
C16: Legend: CO- CO AVAILED, E-EXTRA DUTY

Sheet Sep
B1: Attendance Tracker | AF1: September 2023
A4: CF Balance | B4: Name | C4: 1 | D4: 2 | E4: 3 | F4: 4 | G4: 5 | H4: 6 | I4: 7 | J4: 8 | K4: 9 | L4: 10 | M4: 11 | N4: 12 | O4: 13 | P4: 14 | Q4: 15 | R4: 16 | S4: 17 | T4: 18 | U4: 19 | V4: 20 | W4: 21 | X4: 22 | Y4: 23 | Z4: 24 | AA4: 25 | AB4: 26 | AC4: 27 | AD4: 28 | AE4: 29 | AF4: 30 | AG4: CO Availed this month | AH4: Extra Working days this month | AI4: Addition this month
C5: Fri | D5: Sat | E5: Sun | F5: Mon | G5: Tue | H5: Wed | I5: Thu | J5: Fri | K5: Sat | L5: Sun | M5: Mon | N5: Tue | O5: Wed | P5: Thu | Q5: Fri | R5: Sat | S5: Sun | T5: Mon | U5: Tue | V5: Wed | W5: Thu | X5: Fri | Y5: Sat | Z5: Sun | AA5: Mon | AB5: Tue | AC5: Wed | AD5: Thu | AE5: Fri | AF5: Sat
A6: =Aug!A6+Aug!AI6+Aug!AJ6-Aug!AH6 -> -4 | B6: =Jan!B6 -> KC Tirkey | C6: CO | E6: E | H6: E | L6: E | V6: co | W6: co | AE6: co | AG6: =COUNTIF(B6:AF6, "CO") -> 4 | AH6: =COUNTIF(B6:AF6, "E") -> 3 | AI6: 1
A7: =Aug!A7+Aug!AI7+Aug!AJ7-Aug!AH7 -> 21 | B7: =Jan!B7 -> GN Madhei | C7: E | D7: E | F7: E | X7: E | Z7: E | AE7: E | AG7: =COUNTIF(B7:AF7, "CO") -> 0 | AH7: =COUNTIF(B7:AF7, "E") -> 6 | AI7: 1
A8: =Aug!A8+Aug!AI8+Aug!AJ8-Aug!AH8 -> 40 | B8: =Jan!B9 -> S Lakra | K8: E | T8: co | AE8: E | AG8: =COUNTIF(B8:AF8, "CO") -> 1 | AH8: =COUNTIF(B8:AF8, "E") -> 2 | AI8: 1
A9: =Aug!A9+Aug!AI9+Aug!AJ9-Aug!AH9 -> 40 | B9: =Jan!B10 -> SK Maharana | AD9: E | AF9: E | AG9: =COUNTIF(B9:AF9, "CO") -> 0 | AH9: =COUNTIF(B9:AF9, "E") -> 2 | AI9: 1
A10: =Aug!A10+Aug!AI10+Aug!AJ10-Aug!AH10 -> 39 | B10: =Jan!B11 -> PK Sahoo Sr | C10: CO | D10: CO | G10: E | I10: E | V10: E | W10: E | AF10: E | AG10: =COUNTIF(B10:AF10, "CO") -> 2 | AH10: =COUNTIF(B10:AF10, "E") -> 5 | AI10: 1
A11: =Aug!A11+Aug!AI11+Aug!AJ11-Aug!AH11 -> 60 | B11: =Jan!B12 -> RK Singh | AG11: =COUNTIF(B11:AF11, "CO") -> 0 | AH11: =COUNTIF(B11:AF11, "E") -> 0 | AI11: 1
A12: =Aug!A12+Aug!AI12+Aug!AJ12-Aug!AH12 -> 57 | B12: =Jan!B16 -> M Bishi | AG12: =COUNTIF(B12:AF12, "CO") -> 0 | AH12: =COUNTIF(B12:AF12, "E") -> 0 | AI12: 1
A13: =Aug!A13+Aug!AI13+Aug!AJ13-Aug!AH13 -> 25 | B13: =Jan!B17 -> S C Behera | AA13: co | AB13: co | AG13: =COUNTIF(B13:AF13, "CO") -> 2 | AH13: =COUNTIF(B13:AF13, "E") -> 0 | AI13: 1
A14: =Aug!A14+Aug!AI14+Aug!AJ14-Aug!AH14 -> 24 | B14: =Jan!B14 -> PK Sahoo Jr | D14: CO | E14: CO | F14: CO | G14: CO | H14: CO | L14: CO | AF14: co | AG14: =COUNTIF(B14:AF14, "CO") -> 7 | AH14: =COUNTIF(B14:AF14, "E") -> 0 | AI14: 1
A15: =Aug!A15+Aug!AI15+Aug!AJ15-Aug!AH15 -> 41 | B15: =Jan!B15 -> D Pangi | AG15: =COUNTIF(B15:AF15, "CO") -> 0 | AH15: =COUNTIF(B15:AF15, "E") -> 0 | AI15: 1
C16: Legend: CO- CO AVAILED, E-EXTRA DUTY

Sheet Oct
B1: Attendance Tracker | AE1: October 2023
A4: CF Balance | B4: Name | C4: 1 | D4: 2 | E4: 3 | F4: 4 | G4: 5 | H4: 6 | I4: 7 | J4: 8 | K4: 9 | L4: 10 | M4: 11 | N4: 12 | O4: 13 | P4: 14 | Q4: 15 | R4: 16 | S4: 17 | T4: 18 | U4: 19 | V4: 20 | W4: 21 | X4: 22 | Y4: 23 | Z4: 24 | AA4: 25 | AB4: 26 | AC4: 27 | AD4: 28 | AE4: 29 | AF4: 30 | AG4: 31 | AH4: CO Availed this month | AI4: Extra Working days this month | AJ4: Addition this month
C5: Sun | D5: Mon | E5: Tue | F5: Wed | G5: Thu | H5: Fri | I5: Sat | J5: Sun | K5: Mon | L5: Tue | M5: Wed | N5: Thu | O5: Fri | P5: Sat | Q5: Sun | R5: Mon | S5: Tue | T5: Wed | U5: Thu | V5: Fri | W5: Sat | X5: Sun | Y5: Mon | Z5: Tue | AA5: Wed | AB5: Thu | AC5: Fri | AD5: Sat | AE5: Sun | AF5: Mon | AG5: Tue
A6: =Sep!A6+Sep!AI6+Sep!AH6-Sep!AG6 -> -4 | B6: =Jan!B6 -> KC Tirkey | Q6: E | V6: E | AA6: E | AB6: E | AD6: E | AH6: =COUNTIF(C6:AG6, "CO") -> 0 | AI6: =COUNTIF(C6:AG6, "E") -> 5 | AJ6: 1
A7: =Sep!A7+Sep!AI7+Sep!AH7-Sep!AG7 -> 28 | B7: =Jan!B7 -> GN Madhei | N7: E | Q7: E | V7: E | W7: E | X7: E | AB7: co | AC7: co | AD7: co | AE7: co | AF7: co | AG7: co | AH7: =COUNTIF(C7:AG7, "CO") -> 6 | AI7: =COUNTIF(C7:AG7, "E") -> 5 | AJ7: 1
A8: =Sep!A8+Sep!AI8+Sep!AH8-Sep!AG8 -> 42 | B8: =Jan!B9 -> S Lakra | O8: co | P8: co | X8: E | AC8: E | AH8: =COUNTIF(C8:AG8, "CO") -> 2 | AI8: =COUNTIF(C8:AG8, "E") -> 2 | AJ8: 1
A9: =Sep!A9+Sep!AI9+Sep!AH9-Sep!AG9 -> 43 | B9: =Jan!B10 -> SK Maharana | K9: co | L9: co | O9: E | AB9: co | AF9: co | AG9: co | AH9: =COUNTIF(C9:AG9, "CO") -> 5 | AI9: =COUNTIF(C9:AG9, "E") -> 1 | AJ9: 1
A10: =Sep!A10+Sep!AI10+Sep!AH10-Sep!AG10 -> 43 | B10: =Jan!B11 -> PK Sahoo Sr | L10: E | O10: co | P10: co | V10: co | W10: co | AB10: E | AC10: E | AE10: E | AG10: E | AH10: =COUNTIF(C10:AG10, "CO") -> 4 | AI10: =COUNTIF(C10:AG10, "E") -> 5 | AJ10: 1
A11: =Sep!A11+Sep!AI11+Sep!AH11-Sep!AG11 -> 61 | B11: =Jan!B12 -> RK Singh | AH11: =COUNTIF(C11:AG11, "CO") -> 0 | AI11: =COUNTIF(C11:AG11, "E") -> 0 | AJ11: 1
A12: =Sep!A12+Sep!AI12+Sep!AH12-Sep!AG12 -> 58 | B12: =Jan!B16 -> M Bishi | P12: E | W12: co | X12: co | Y12: co | AA12: co | AC12: co | AE12: co | AH12: =COUNTIF(C12:AG12, "CO") -> 6 | AI12: =COUNTIF(C12:AG12, "E") -> 1 | AJ12: 1
A13: =Sep!A13+Sep!AI13+Sep!AH13-Sep!AG13 -> 24 | B13: =Jan!B17 -> S C Behera | R13: co | AH13: =COUNTIF(C13:AG13, "CO") -> 1 | AI13: =COUNTIF(C13:AG13, "E") -> 0 | AJ13: 1
A14: =Sep!A14+Sep!AI14+Sep!AH14-Sep!AG14 -> 18 | B14: =Jan!B14 -> PK Sahoo Jr | P14: E | Q14: co | AF14: E | AG14: E | AH14: =COUNTIF(C14:AG14, "CO") -> 1 | AI14: =COUNTIF(C14:AG14, "E") -> 3 | AJ14: 1
A15: =Sep!A15+Sep!AI15+Sep!AH15-Sep!AG15 -> 42 | B15: =Jan!B15 -> D Pangi | AH15: =COUNTIF(C15:AG15, "CO") -> 0 | AI15: =COUNTIF(C15:AG15, "E") -> 0 | AJ15: 1
C16: Legend: CO- CO AVAILED, E-EXTRA DUTY

Sheet Nov
B1: Attendance Tracker | AE1: November 2023
A4: CF Balance | B4: Name | C4: 1 | D4: 2 | E4: 3 | F4: 4 | G4: 5 | H4: 6 | I4: 7 | J4: 8 | K4: 9 | L4: 10 | M4: 11 | N4: 12 | O4: 13 | P4: 14 | Q4: 15 | R4: 16 | S4: 17 | T4: 18 | U4: 19 | V4: 20 | W4: 21 | X4: 22 | Y4: 23 | Z4: 24 | AA4: 25 | AB4: 26 | AC4: 27 | AD4: 28 | AE4: 29 | AF4: 30 | AG4: CO Availed this month | AH4: Extra Working days this month | AI4: Addition this month
C5: Wed | D5: Thu | E5: Fri | F5: Sat | G5: Sun | H5: Mon | I5: Tue | J5: Wed | K5: Thu | L5: Fri | M5: Sat | N5: Sun | O5: Mon | P5: Tue | Q5: Wed | R5: Thu | S5: Fri | T5: Sat | U5: Sun | V5: Mon | W5: Tue | X5: Wed | Y5: Thu | Z5: Fri | AA5: Sat | AB5: Sun | AC5: Mon | AD5: Tue | AE5: Wed | AF5: Thu
A6: =Oct!A6+Oct!AI6+Oct!AJ6-Oct!AH6 -> 2 | B6: =Jan!B6 -> KC Tirkey | E6: E | G6: E | H6: E | N6: co | O6: co | Y6: E | Z6: E | AG6: =COUNTIF(B6:AF6, "CO") -> 2 | AH6: =COUNTIF(B6:AF6, "E") -> 5 | AI6: 1
A7: =Oct!A7+Oct!AI7+Oct!AJ7-Oct!AH7 -> 28 | B7: =Jan!B7 -> GN Madhei | E7: co | F7: co | G7: co | H7: co | I7: co | O7: E | R7: E | T7: CO | W7: E | X7: CO | Y7: CO | AG7: =COUNTIF(B7:AF7, "CO") -> 8 | AH7: =COUNTIF(B7:AF7, "E") -> 3 | AI7: 1
A8: =Oct!A8+Oct!AI8+Oct!AJ8-Oct!AH8 -> 43 | B8: =Jan!B9 -> S Lakra | D8: E | F8: E | L8: E | U8: E | AA8: E | AG8: =COUNTIF(B8:AF8, "CO") -> 0 | AH8: =COUNTIF(B8:AF8, "E") -> 5 | AI8: 1
A9: =Oct!A9+Oct!AI9+Oct!AJ9-Oct!AH9 -> 40 | B9: =Jan!B10 -> SK Maharana | D9: E | K9: E | M9: E | P9: co | Q9: co | R9: CO | AG9: =COUNTIF(B9:AF9, "CO") -> 3 | AH9: =COUNTIF(B9:AF9, "E") -> 3 | AI9: 1
A10: =Oct!A10+Oct!AI10+Oct!AJ10-Oct!AH10 -> 45 | B10: =Jan!B11 -> PK Sahoo Sr | L10: E | AG10: =COUNTIF(B10:AF10, "CO") -> 0 | AH10: =COUNTIF(B10:AF10, "E") -> 1 | AI10: 1
A11: =Oct!A11+Oct!AI11+Oct!AJ11-Oct!AH11 -> 62 | B11: =Jan!B12 -> RK Singh | T11: CO | AG11: =COUNTIF(B11:AF11, "CO") -> 1 | AH11: =COUNTIF(B11:AF11, "E") -> 0 | AI11: 1
A12: =Oct!A12+Oct!AI12+Oct!AJ12-Oct!AH12 -> 54 | B12: =Jan!B16 -> M Bishi | AG12: =COUNTIF(B12:AF12, "CO") -> 0 | AH12: =COUNTIF(B12:AF12, "E") -> 0 | AI12: 1
A13: =Oct!A13+Oct!AI13+Oct!AJ13-Oct!AH13 -> 24 | B13: =Jan!B17 -> S C Behera | E13: co | F13: co | M13: co | X13: CO | Y13: CO | AG13: =COUNTIF(B13:AF13, "CO") -> 5 | AH13: =COUNTIF(B13:AF13, "E") -> 0 | AI13: 1
A14: =Oct!A14+Oct!AI14+Oct!AJ14-Oct!AH14 -> 21 | B14: =Jan!B14 -> PK Sahoo Jr | N14: co | Y14: E | AG14: =COUNTIF(B14:AF14, "CO") -> 1 | AH14: =COUNTIF(B14:AF14, "E") -> 1 | AI14: 1
A15: =Oct!A15+Oct!AI15+Oct!AJ15-Oct!AH15 -> 43 | B15: =Jan!B15 -> D Pangi | AG15: =COUNTIF(B15:AF15, "CO") -> 0 | AH15: =COUNTIF(B15:AF15, "E") -> 0 | AI15: 1
C16: Legend: CO- CO AVAILED, E-EXTRA DUTY

Sheet Dec
B1: Attendance Tracker | AE1: December 2023
A4: CF Balance | B4: Name | C4: 1 | D4: 2 | E4: 3 | F4: 4 | G4: 5 | H4: 6 | I4: 7 | J4: 8 | K4: 9 | L4: 10 | M4: 11 | N4: 12 | O4: 13 | P4: 14 | Q4: 15 | R4: 16 | S4: 17 | T4: 18 | U4: 19 | V4: 20 | W4: 21 | X4: 22 | Y4: 23 | Z4: 24 | AA4: 25 | AB4: 26 | AC4: 27 | AD4: 28 | AE4: 29 | AF4: 30 | AG4: 31 | AH4: CO Availed this month | AI4: Extra Working days this month | AJ4: Addition this month
C5: Fri | D5: Sat | E5: Sun | F5: Mon | G5: Tue | H5: Wed | I5: Thu | J5: Fri | K5: Sat | L5: Sun | M5: Mon | N5: Tue | O5: Wed | P5: Thu | Q5: Fri | R5: Sat | S5: Sun | T5: Mon | U5: Tue | V5: Wed | W5: Thu | X5: Fri | Y5: Sat | Z5: Sun | AA5: Mon | AB5: Tue | AC5: Wed | AD5: Thu | AE5: Fri | AF5: Sat | AG5: Sun
A6: =Nov!A6+Nov!AI6+Nov!AH6-Nov!AG6 -> 6 | B6: =Jan!B6 -> KC Tirkey | L6: CO | M6: CO | Q6: CO | S6: E | T6: E | U6: E | W6: E | Z6: CO | AA6: CO | AB6: CO | AC6: CO | AD6: CO | AE6: CO | AH6: =COUNTIF(C6:AG6, "CO") -> 9 | AI6: =COUNTIF(C6:AG6, "E") -> 4 | AJ6: 1
A7: =Nov!A7+Nov!AI7+Nov!AH7-Nov!AG7 -> 24 | B7: =Jan!B7 -> GN Madhei | D7: E | K7: E | P7: CO | Q7: CO | S7: CO | T7: CO | U7: CO | W7: CO | X7: CO | AA7: E | AB7: E | AC7: E | AD7: E | AE7: E | AG7: E | AH7: =COUNTIF(C7:AG7, "CO") -> 7 | AI7: =COUNTIF(C7:AG7, "E") -> 8 | AJ7: 1
A8: =Nov!A8+Nov!AI8+Nov!AH8-Nov!AG8 -> 49 | B8: =Jan!B9 -> S Lakra | R8: E | V8: E | W8: E | AD8: CO | AE8: CO | AF8: CO | AG8: CO | AH8: =COUNTIF(C8:AG8, "CO") -> 4 | AI8: =COUNTIF(C8:AG8, "E") -> 3 | AJ8: 1
A9: =Nov!A9+Nov!AI9+Nov!AH9-Nov!AG9 -> 41 | B9: =Jan!B10 -> SK Maharana | G9: E | T9: E | U9: E | AC9: CO | AD9: CO | AE9: CO | AF9: CO | AH9: =COUNTIF(C9:AG9, "CO") -> 4 | AI9: =COUNTIF(C9:AG9, "E") -> 3 | AJ9: 1
A10: =Nov!A10+Nov!AI10+Nov!AH10-Nov!AG10 -> 47 | B10: =Jan!B11 -> PK Sahoo Sr | C10: CO | D10: CO | E10: CO | G10: CO | H10: CO | I10: CO | J10: CO | Q10: CO | AB10: E | AC10: E | AH10: =COUNTIF(C10:AG10, "CO") -> 8 | AI10: =COUNTIF(C10:AG10, "E") -> 2 | AJ10: 1
A11: =Nov!A11+Nov!AI11+Nov!AH11-Nov!AG11 -> 62 | B11: =Jan!B12 -> RK Singh | F11: CO | G11: CO | H11: CO | J11: CO | N11: CO | AH11: =COUNTIF(C11:AG11, "CO") -> 5 | AI11: =COUNTIF(C11:AG11, "E") -> 0 | AJ11: 1
A12: =Nov!A12+Nov!AI12+Nov!AH12-Nov!AG12 -> 55 | B12: =Jan!B16 -> M Bishi | C12: E | E12: E | Q12: CO | R12: CO | X12: E | Y12: E | Z12: E | AA12: E | AF12: CO | AH12: =COUNTIF(C12:AG12, "CO") -> 3 | AI12: =COUNTIF(C12:AG12, "E") -> 6 | AJ12: 1
A13: =Nov!A13+Nov!AI13+Nov!AH13-Nov!AG13 -> 20 | B13: =Jan!B17 -> S C Behera | F13: CO | Q13: CO | R13: CO | AB13: CO | AH13: =COUNTIF(C13:AG13, "CO") -> 4 | AI13: =COUNTIF(C13:AG13, "E") -> 0 | AJ13: 1
A14: =Nov!A14+Nov!AI14+Nov!AH14-Nov!AG14 -> 22 | B14: =Jan!B14 -> PK Sahoo Jr | K14: CO | Q14: E | R14: E | V14: CO | Z14: CO | AA14: CO | AB14: CO | AC14: CO | AD14: CO | AH14: =COUNTIF(C14:AG14, "CO") -> 7 | AI14: =COUNTIF(C14:AG14, "E") -> 2 | AJ14: 1
A15: =Nov!A15+Nov!AI15+Nov!AH15-Nov!AG15 -> 44 | B15: =Jan!B15 -> D Pangi | AH15: =COUNTIF(C15:AG15, "CO") -> 0 | AI15: =COUNTIF(C15:AG15, "E") -> 0 | AJ15: 1
C16: Legend: CO- CO AVAILED, E-EXTRA DUTY

Sheet Jan24
B1: Attendance Tracker | AE1: January 2024
A4: CF Balance | B4: Name | C4: 1 | D4: 2 | E4: 3 | F4: 4 | G4: 5 | H4: 6 | I4: 7 | J4: 8 | K4: 9 | L4: 10 | M4: 11 | N4: 12 | O4: 13 | P4: 14 | Q4: 15 | R4: 16 | S4: 17 | T4: 18 | U4: 19 | V4: 20 | W4: 21 | X4: 22 | Y4: 23 | Z4: 24 | AA4: 25 | AB4: 26 | AC4: 27 | AD4: 28 | AE4: 29 | AF4: 30 | AG4: 31 | AH4: CO Availed this month | AI4: Extra Working days this month | AJ4: Addition this month
C5: Mon | D5: Tue | E5: Wed | F5: Thu | G5: Fri | H5: Sat | I5: Sun | J5: Mon | K5: Tue | L5: Wed | M5: Thu | N5: Fri | O5: Sat | P5: Sun | Q5: Mon | R5: Tue | S5: Wed | T5: Thu | U5: Fri | V5: Sat | W5: Sun | X5: Mon | Y5: Tue | Z5: Wed | AA5: Thu | AB5: Fri | AC5: Sat | AD5: Sun | AE5: Mon | AF5: Tue | AG5: Wed
A6: =Dec!A6+Dec!AI6+Dec!AJ6-Dec!AH6 -> 2 | B6: =Jan!B6 -> KC Tirkey | L6: CO | M6: CO | N6: CO | T6: CO | U6: CO | X6: E | Y6: E | AE6: E | AF6: E | AG6: E | AH6: =COUNTIF(C6:AG6, "CO") -> 5 | AI6: =COUNTIF(C6:AG6, "E") -> 5 | AJ6: 1
A7: =Dec!A7+Dec!AI7+Dec!AJ7-Dec!AH7 -> 26 | B7: =Jan!B7 -> GN Madhei | D7: E | P7: CO | Q7: CO | R7: CO | U7: CO | V7: CO | W7: CO | X7: CO | AD7: E | AH7: =COUNTIF(C7:AG7, "CO") -> 7 | AI7: =COUNTIF(C7:AG7, "E") -> 2 | AJ7: 1
A8: 65 | B8: =Jan!B18 -> S K Sahoo | P8: E | V8: E | W8: E | AH8: =COUNTIF(C8:AG8, "CO") -> 0 | AI8: =COUNTIF(C8:AG8, "E") -> 3 | AJ8: 1
A9: =Dec!A8+Dec!AI8+Dec!AJ8-Dec!AH8 -> 49 | B9: =Jan!B9 -> S Lakra | J9: E | O9: E | P9: E | U9: E | W9: E | AE9: CO | AF9: CO | AG9: CO | AH9: =COUNTIF(C9:AG9, "CO") -> 3 | AI9: =COUNTIF(C9:AG9, "E") -> 5 | AJ9: 1
A10: =Dec!A9+Dec!AI9+Dec!AJ9-Dec!AH9 -> 41 | B10: =Jan!B10 -> SK Maharana | T10: E | AH10: =COUNTIF(C10:AG10, "CO") -> 0 | AI10: =COUNTIF(C10:AG10, "E") -> 1 | AJ10: 1
A11: =Dec!A11+Dec!AI11+Dec!AJ11-Dec!AH11 -> 58 | B11: =Jan!B12 -> RK Singh | AG11: CO | AH11: =COUNTIF(C11:AG11, "CO") -> 1 | AI11: =COUNTIF(C11:AG11, "E") -> 0 | AJ11: 1
A12: =Dec!A12+Dec!AI12+Dec!AJ12-Dec!AH12 -> 59 | B12: =Jan!B16 -> M Bishi | E12: E | R12: E | S12: E | AH12: =COUNTIF(C12:AG12, "CO") -> 0 | AI12: =COUNTIF(C12:AG12, "E") -> 3 | AJ12: 1
A13: =Dec!A13+Dec!AI13+Dec!AJ13-Dec!AH13 -> 17 | B13: =Jan!B17 -> S C Behera | C13: CO | AA13: CO | AC13: CO | AH13: =COUNTIF(C13:AG13, "CO") -> 3 | AI13: =COUNTIF(C13:AG13, "E") -> 0 | AJ13: 1
A14: =Dec!A14+Dec!AI14+Dec!AJ14-Dec!AH14 -> 18 | B14: =Jan!B14 -> PK Sahoo Jr | F14: E | R14: E | S14: E | V14: CO | W14: CO | AH14: =COUNTIF(C14:AG14, "CO") -> 2 | AI14: =COUNTIF(C14:AG14, "E") -> 3 | AJ14: 1
A15: =Dec!A15+Dec!AI15+Dec!AJ15-Dec!AH15 -> 45 | B15: =Jan!B15 -> D Pangi | N15: CO | AH15: =COUNTIF(C15:AG15, "CO") -> 1 | AI15: =COUNTIF(C15:AG15, "E") -> 0 | AJ15: 1
C16: Legend: CO- CO AVAILED, E-EXTRA DUTY

Sheet FEB24
B1: Attendance Tracker | AE1: February 2024
A4: CF Balance | B4: Name | C4: 1 | D4: 2 | E4: 3 | F4: 4 | G4: 5 | H4: 6 | I4: 7 | J4: 8 | K4: 9 | L4: 10 | M4: 11 | N4: 12 | O4: 13 | P4: 14 | Q4: 15 | R4: 16 | S4: 17 | T4: 18 | U4: 19 | V4: 20 | W4: 21 | X4: 22 | Y4: 23 | Z4: 24 | AA4: 25 | AB4: 26 | AC4: 27 | AD4: 28 | AE4: 29 | AH4: CO Availed this month | AI4: Extra Working days this month | AJ4: Addition this month
C5: Thu | D5: Fri | E5: Sat | F5: Sun | G5: Mon | H5: Tue | I5: Wed | J5: Thu | K5: Fri | L5: Sat | M5: Sun | N5: Mon | O5: Tue | P5: Wed | Q5: Thu | R5: Fri | S5: Sat | T5: Sun | U5: Mon | V5: Tue | W5: Wed | X5: Thu | Y5: Fri | Z5: Sat | AA5: Sun | AB5: Mon | AC5: Tue | AD5: Wed | AE5: Thu
A6: ='Jan24'!A6+'Jan24'!AI6+'Jan24'!AJ6-'Jan24'!AH6 -> 3 | B6: =Jan!B6 -> KC Tirkey | I6: CO | J6: CO | K6: CO | M6: CO | N6: CO | W6: E | X6: E | Y6: E | AA6: E | AB6: E | AD6: E | AE6: E | AH6: =COUNTIF(C6:AG6, "CO") -> 5 | AI6: =COUNTIF(C6:AG6, "E") -> 7 | AJ6: 1
A7: ='Jan24'!A7+'Jan24'!AI7+'Jan24'!AJ7-'Jan24'!AH7 -> 22 | B7: =Jan!B7 -> GN Madhei | C7: E | D7: E | M7: CO | N7: CO | O7: CO | Q7: CO | V7: E | AH7: =COUNTIF(C7:AG7, "CO") -> 4 | AI7: =COUNTIF(C7:AG7, "E") -> 3 | AJ7: 1
A8: ='Jan24'!A8+'Jan24'!AI8+'Jan24'!AJ8-'Jan24'!AH8 -> 69 | B8: =Jan!B18 -> S K Sahoo | D8: E | E8: E | F8: E | K8: E | M8: CO | O8: CO | P8: CO | Q8: CO | T8: E | AD8: CO | AE8: CO | AH8: =COUNTIF(C8:AG8, "CO") -> 6 | AI8: =COUNTIF(C8:AG8, "E") -> 5 | AJ8: 1
A9: ='Jan24'!A9+'Jan24'!AI9+'Jan24'!AJ9-'Jan24'!AH9 -> 52 | B9: =Jan!B9 -> S Lakra | J9: E | K9: E | W9: CO | X9: CO | Y9: CO | Z9: CO | AH9: =COUNTIF(C9:AG9, "CO") -> 4 | AI9: =COUNTIF(C9:AG9, "E") -> 2 | AJ9: 1
A10: ='Jan24'!A10+'Jan24'!AI10+'Jan24'!AJ10-'Jan24'!AH10 -> 43 | B10: =Jan!B10 -> SK Maharana | C10: CO | AH10: =COUNTIF(C10:AG10, "CO") -> 1 | AI10: =COUNTIF(C10:AG10, "E") -> 0 | AJ10: 1
A11: ='Jan24'!A11+'Jan24'!AI11+'Jan24'!AJ11-'Jan24'!AH11 -> 58 | B11: =Jan!B12 -> RK Singh | AH11: =COUNTIF(C11:AG11, "CO") -> 0 | AI11: =COUNTIF(C11:AG11, "E") -> 0 | AJ11: 1
A12: ='Jan24'!A12+'Jan24'!AI12+'Jan24'!AJ12-'Jan24'!AH12 -> 63 | B12: =Jan!B16 -> M Bishi | K12: CO | L12: CO | AH12: =COUNTIF(C12:AG12, "CO") -> 2 | AI12: =COUNTIF(C12:AG12, "E") -> 0 | AJ12: 1
A13: ='Jan24'!A13+'Jan24'!AI13+'Jan24'!AJ13-'Jan24'!AH13 -> 15 | B13: =Jan!B17 -> S C Behera | AH13: =COUNTIF(C13:AG13, "CO") -> 0 | AI13: =COUNTIF(C13:AG13, "E") -> 0 | AJ13: 1
A14: ='Jan24'!A14+'Jan24'!AI14+'Jan24'!AJ14-'Jan24'!AH14 -> 20 | B14: =Jan!B14 -> PK Sahoo Jr | E14: CO | F14: CO | T14: CO | AH14: =COUNTIF(C14:AG14, "CO") -> 3 | AI14: =COUNTIF(C14:AG14, "E") -> 0 | AJ14: 1
A15: ='Jan24'!A15+'Jan24'!AI15+'Jan24'!AJ15-'Jan24'!AH15 -> 45 | B15: =Jan!B15 -> D Pangi | AH15: =COUNTIF(C15:AG15, "CO") -> 0 | AI15: =COUNTIF(C15:AG15, "E") -> 0 | AJ15: 1
C16: Legend: CO- CO AVAILED, E-EXTRA DUTY

Sheet mAR24
B1: Attendance Tracker | AE1: mARCH 2024
A4: CF Balance | B4: Name | C4: 1 | D4: 2 | E4: 3 | F4: 4 | G4: 5 | H4: 6 | I4: 7 | J4: 8 | K4: 9 | L4: 10 | M4: 11 | N4: 12 | O4: 13 | P4: 14 | Q4: 15 | R4: 16 | S4: 17 | T4: 18 | U4: 19 | V4: 20 | W4: 21 | X4: 22 | Y4: 23 | Z4: 24 | AA4: 25 | AB4: 26 | AC4: 27 | AD4: 28 | AE4: 29 | AF4: 30 | AG4: 31 | AH4: CO Availed this month | AI4: Extra Working days this month | AJ4: Addition this month
C5: Fri | D5: Sat | E5: Sun | F5: Mon | G5: Tue | H5: Wed | I5: Thu | J5: Fri | K5: Sat | L5: Sun | M5: Mon | N5: Tue | O5: Wed | P5: Thu | Q5: Fri | R5: Sat | S5: Sun | T5: Mon | U5: Tue | V5: Wed | W5: Thu | X5: Fri | Y5: Sat | Z5: Sun | AA5: Mon | AB5: Tue | AC5: Wed | AD5: Thu | AE5: Fri | AF5: Sat | AG5: Sun
A6: ='FEB24'!A6+'FEB24'!AI6+'FEB24'!AJ6-'FEB24'!AH6 -> 6 | B6: =Jan!B6 -> KC Tirkey | C6: E | E6: CO | G6: E | H6: E | J6: E | L6: E | M6: E | N6: E | O6: E | P6: E | T6: E | V6: E | AC6: E | AD6: E | AH6: =COUNTIF(C6:AG6, "CO") -> 1 | AI6: =COUNTIF(C6:AG6, "E") -> 13 | AJ6: 1
A7: ='FEB24'!A7+'FEB24'!AI7+'FEB24'!AJ7-'FEB24'!AH7 -> 22 | B7: =Jan!B7 -> GN Madhei | E7: E | J7: E | K7: E | M7: E | R7: E | W7: E | Z7: E | AH7: =COUNTIF(C7:AG7, "CO") -> 0 | AI7: =COUNTIF(C7:AG7, "E") -> 7 | AJ7: 1
A8: ='FEB24'!A8+'FEB24'!AI8+'FEB24'!AJ8-'FEB24'!AH8 -> 69 | B8: =Jan!B18 -> S K Sahoo | C8: CO | D8: CO | E8: CO | G8: CO | H8: CO | I8: CO | J8: CO | K8: E | L8: E | N8: E | U8: CO | V8: CO | X8: E | AH8: =COUNTIF(C8:AG8, "CO") -> 9 | AI8: =COUNTIF(C8:AG8, "E") -> 4 | AJ8: 1
A9: ='FEB24'!A9+'FEB24'!AI9+'FEB24'!AJ9-'FEB24'!AH9 -> 51 | B9: =Jan!B9 -> S Lakra | K9: E | M9: E | R9: CO | S9: CO | T9: CO | W9: CO | X9: CO | Y9: CO | Z9: CO | AA9: CO | AH9: =COUNTIF(C9:AG9, "CO") -> 8 | AI9: =COUNTIF(C9:AG9, "E") -> 2 | AJ9: 1
A10: ='FEB24'!A10+'FEB24'!AI10+'FEB24'!AJ10-'FEB24'!AH10 -> 43 | B10: =Jan!B10 -> SK Maharana | G10: CO | H10: CO | I10: CO | M10: CO | O10: CO | AA10: E | AH10: =COUNTIF(C10:AG10, "CO") -> 5 | AI10: =COUNTIF(C10:AG10, "E") -> 1 | AJ10: 1
A11: ='FEB24'!A11+'FEB24'!AI11+'FEB24'!AJ11-'FEB24'!AH11 -> 59 | B11: =Jan!B12 -> RK Singh | AH11: =COUNTIF(C11:AG11, "CO") -> 0 | AI11: =COUNTIF(C11:AG11, "E") -> 0 | AJ11: 1
A12: ='FEB24'!A12+'FEB24'!AI12+'FEB24'!AJ12-'FEB24'!AH12 -> 62 | B12: =Jan!B16 -> M Bishi | D12: E | J12: CO | K12: CO | L12: CO | M12: CO | N12: CO | O12: CO | S12: E | V12: E | AD12: CO | AE12: CO | AF12: CO | AH12: =COUNTIF(C12:AG12, "CO") -> 9 | AI12: =COUNTIF(C12:AG12, "E") -> 3 | AJ12: 1
A13: ='FEB24'!A13+'FEB24'!AI13+'FEB24'!AJ13-'FEB24'!AH13 -> 16 | B13: =Jan!B17 -> S C Behera | AF13: CO | AH13: =COUNTIF(C13:AG13, "CO") -> 1 | AI13: =COUNTIF(C13:AG13, "E") -> 0 | AJ13: 1
A14: ='FEB24'!A14+'FEB24'!AI14+'FEB24'!AJ14-'FEB24'!AH14 -> 18 | B14: =Jan!B14 -> PK Sahoo Jr | G14: CO | H14: CO | L14: CO | M14: CO | N14: CO | O14: CO | P14: CO | AH14: =COUNTIF(C14:AG14, "CO") -> 7 | AI14: =COUNTIF(C14:AG14, "E") -> 0 | AJ14: 1
A15: ='FEB24'!A15+'FEB24'!AI15+'FEB24'!AJ15-'FEB24'!AH15 -> 46 | B15: =Jan!B15 -> D Pangi | AH15: =COUNTIF(C15:AG15, "CO") -> 0 | AI15: =COUNTIF(C15:AG15, "E") -> 0 | AJ15: 1
C16: Legend: CO- CO AVAILED, E-EXTRA DUTY

Sheet Apr24
B1: Attendance Tracker | AE1: April 2024
A4: CF Balance | B4: Name | C4: 1 | D4: 2 | E4: 3 | F4: 4 | G4: 5 | H4: 6 | I4: 7 | J4: 8 | K4: 9 | L4: 10 | M4: 11 | N4: 12 | O4: 13 | P4: 14 | Q4: 15 | R4: 16 | S4: 17 | T4: 18 | U4: 19 | V4: 20 | W4: 21 | X4: 22 | Y4: 23 | Z4: 24 | AA4: 25 | AB4: 26 | AC4: 27 | AD4: 28 | AE4: 29 | AF4: 30 | AH4: CO Availed this month | AI4: Extra Working days this month | AJ4: Addition this month
C5: Mon | D5: Tue | E5: Wed | F5: Thu | G5: Fri | H5: Sat | I5: Sun | J5: Mon | K5: Tue | L5: Wed | M5: Thu | N5: Fri | O5: Sat | P5: Sun | Q5: Mon | R5: Tue | S5: Wed | T5: Thu | U5: Fri | V5: Sat | W5: Sun | X5: Mon | Y5: Tue | Z5: Wed | AA5: Thu | AB5: Fri | AC5: Sat | AD5: Sun | AE5: Mon | AF5: Tue
A6: ='mAR24'!A6+'mAR24'!AI6+'mAR24'!AJ6-'mAR24'!AH6 -> 19 | B6: =Jan!B6 -> KC Tirkey | E6: CO | F6: CO | G6: CO | I6: CO | J6: CO | K6: CO | U6: E | Z6: CO | AA6: CO | AB6: CO | AD6: CO | AE6: CO | AF6: CO | AH6: =COUNTIF(C6:AG6, "CO") -> 12 | AI6: =COUNTIF(C6:AG6, "E") -> 1 | AJ6: 1
A7: ='mAR24'!A7+'mAR24'!AI7+'mAR24'!AJ7-'mAR24'!AH7 -> 30 | B7: =Jan!B7 -> GN Madhei | F7: CO | G7: CO | H7: CO | I7: CO | J7: CO | K7: CO | M7: CO | V7: E | Y7: E | AC7: E | AD7: E | AE7: E | AF7: E | AH7: =COUNTIF(C7:AG7, "CO") -> 7 | AI7: =COUNTIF(C7:AG7, "E") -> 6 | AJ7: 1
A8: ='mAR24'!A8+'mAR24'!AI8+'mAR24'!AJ8-'mAR24'!AH8 -> 65 | B8: =Jan!B18 -> S K Sahoo | I8: E | J8: E | W8: E | AB8: E | AD8: E | AE8: E | AH8: =COUNTIF(C8:AG8, "CO") -> 0 | AI8: =COUNTIF(C8:AG8, "E") -> 6 | AJ8: 1
A9: ='mAR24'!A9+'mAR24'!AI9+'mAR24'!AJ9-'mAR24'!AH9 -> 46 | B9: =Jan!B9 -> S Lakra | E9: E | G9: E | Z9: E | AA9: E | AC9: E | AH9: =COUNTIF(C9:AG9, "CO") -> 0 | AI9: =COUNTIF(C9:AG9, "E") -> 5 | AJ9: 1
A10: ='mAR24'!A10+'mAR24'!AI10+'mAR24'!AJ10-'mAR24'!AH10 -> 40 | B10: =Jan!B10 -> SK Maharana | F10: E | K10: E | AH10: =COUNTIF(C10:AG10, "CO") -> 0 | AI10: =COUNTIF(C10:AG10, "E") -> 2 | AJ10: 1
A11: 28 | B11: =Jan!B19 -> A K Dalai | F11: E | G11: E | I11: E | L11: E | U11: CO | V11: CO | W11: CO | Y11: CO | Z11: CO | AA11: CO | AB11: CO | AC11: CO | AD11: CO | AH11: =COUNTIF(C11:AG11, "CO") -> 9 | AI11: =COUNTIF(C11:AG11, "E") -> 4 | AJ11: 1
A12: ='mAR24'!A11+'mAR24'!AI11+'mAR24'!AJ11-'mAR24'!AH11-2 -> 58 | B12: =Jan!B12 -> RK Singh | F12: CO | AH12: =COUNTIF(C12:AG12, "CO") -> 1 | AI12: =COUNTIF(C12:AG12, "E") -> 0 | AJ12: 1
A13: ='mAR24'!A12+'mAR24'!AI12+'mAR24'!AJ12-'mAR24'!AH12 -> 57 | B13: =Jan!B16 -> M Bishi | AD13: CO | AE13: CO | AF13: CO | AH13: =COUNTIF(C13:AG13, "CO") -> 3 | AI13: =COUNTIF(C13:AG13, "E") -> 0 | AJ13: 1
A14: ='mAR24'!A13+'mAR24'!AI13+'mAR24'!AJ13-'mAR24'!AH13 -> 16 | B14: =Jan!B17 -> S C Behera | Z14: CO | AH14: =COUNTIF(C14:AG14, "CO") -> 1 | AI14: =COUNTIF(C14:AG14, "E") -> 0 | AJ14: 1
A15: ='mAR24'!A15+'mAR24'!AI15+'mAR24'!AJ15-'mAR24'!AH15 -> 47 | B15: =Jan!B15 -> D Pangi | AH15: =COUNTIF(C15:AG15, "CO") -> 0 | AI15: =COUNTIF(C15:AG15, "E") -> 0 | AJ15: 1
C16: Legend: CO- CO AVAILED, E-EXTRA DUTY

Sheet mAY24
B1: Attendance Tracker | AE1: May 2024
A4: CF Balance | B4: Name | C4: 1 | D4: 2 | E4: 3 | F4: 4 | G4: 5 | H4: 6 | I4: 7 | J4: 8 | K4: 9 | L4: 10 | M4: 11 | N4: 12 | O4: 13 | P4: 14 | Q4: 15 | R4: 16 | S4: 17 | T4: 18 | U4: 19 | V4: 20 | W4: 21 | X4: 22 | Y4: 23 | Z4: 24 | AA4: 25 | AB4: 26 | AC4: 27 | AD4: 28 | AE4: 29 | AF4: 30 | AG4: 31 | AH4: CO Availed this month | AI4: Extra Working days this month | AJ4: Addition this month
C5: Wed | D5: Thu | E5: Fri | F5: Sat | G5: Sun | H5: Mon | I5: Tue | J5: Wed | K5: Thu | L5: Fri | M5: Sat | N5: Sun | O5: Mon | P5: Tue | Q5: Wed | R5: Thu | S5: Fri | T5: Sat | U5: Sun | V5: Mon | W5: Tue | X5: Wed | Y5: Thu | Z5: Fri | AA5: Sat | AB5: Sun | AC5: Mon | AD5: Tue | AE5: Wed | AF5: Thu | AG5: Fri
A6: ='Apr24'!A6+'Apr24'!AI6+'Apr24'!AJ6-'Apr24'!AH6 -> 9 | B6: =Jan!B6 -> KC Tirkey | E6: E | I6: CO | J6: CO | K6: CO | L6: CO | S6: E | U6: E | W6: E | AB6: CO | AC6: CO | AH6: =COUNTIF(C6:AG6, "CO") -> 6 | AI6: =COUNTIF(C6:AG6, "E") -> 4 | AJ6: 1
A7: ='Apr24'!A7+'Apr24'!AI7+'Apr24'!AJ7-'Apr24'!AH7 -> 30 | B7: =Jan!B7 -> GN Madhei | H7: E | K7: E | R7: CO | S7: CO | T7: CO | U7: CO | V7: CO | W7: CO | Y7: CO | Z7: CO | AA7: CO | AB7: CO | AC7: CO | AD7: CO | AH7: =COUNTIF(C7:AG7, "CO") -> 12 | AI7: =COUNTIF(C7:AG7, "E") -> 2 | AJ7: 1
A8: ='Apr24'!A8+'Apr24'!AI8+'Apr24'!AJ8-'Apr24'!AH8 -> 72 | B8: =Jan!B18 -> S K Sahoo | J8: CO | K8: CO | R8: CO | T8: CO | Z8: E | AH8: =COUNTIF(C8:AG8, "CO") -> 4 | AI8: =COUNTIF(C8:AG8, "E") -> 1 | AJ8: 1
A9: ='Apr24'!A9+'Apr24'!AI9+'Apr24'!AJ9-'Apr24'!AH9 -> 52 | B9: =Jan!B9 -> S Lakra | F9: CO | N9: E | Q9: E | S9: E | Z9: E | AC9: E | AH9: =COUNTIF(C9:AG9, "CO") -> 1 | AI9: =COUNTIF(C9:AG9, "E") -> 5 | AJ9: 1
A10: ='Apr24'!A10+'Apr24'!AI10+'Apr24'!AJ10-'Apr24'!AH10 -> 43 | B10: =Jan!B10 -> SK Maharana | V10: E | X10: E | AC10: CO | AD10: CO | AE10: CO | AF10: CO | AH10: =COUNTIF(C10:AG10, "CO") -> 4 | AI10: =COUNTIF(C10:AG10, "E") -> 2 | AJ10: 1
A11: ='Apr24'!A11+'Apr24'!AI11+'Apr24'!AJ11-'Apr24'!AH11 -> 24 | B11: =Jan!B19 -> A K Dalai | S11: CO | AD11: CO | AH11: =COUNTIF(C11:AG11, "CO") -> 2 | AI11: =COUNTIF(C11:AG11, "E") -> 0 | AJ11: 1
A12: ='Apr24'!A12+'Apr24'!AI12+'Apr24'!AJ12-'Apr24'!AH12 -> 58 | B12: =Jan!B12 -> RK Singh | F12: CO | H12: CO | W12: CO | AH12: =COUNTIF(C12:AG12, "CO") -> 3 | AI12: =COUNTIF(C12:AG12, "E") -> 0 | AJ12: 1
A13: ='Apr24'!A13+'Apr24'!AI13+'Apr24'!AJ13-'Apr24'!AH13 -> 55 | B13: =Jan!B16 -> M Bishi | E13: CO | F13: CO | G13: CO | H13: CO | AA13: E | AH13: =COUNTIF(C13:AG13, "CO") -> 4 | AI13: =COUNTIF(C13:AG13, "E") -> 1 | AJ13: 1
A14: ='Apr24'!A14+'Apr24'!AI14+'Apr24'!AJ14-'Apr24'!AH14 -> 16 | B14: =Jan!B17 -> S C Behera | E14: CO | F14: CO | P14: CO | AH14: =COUNTIF(C14:AG14, "CO") -> 3 | AI14: =COUNTIF(C14:AG14, "E") -> 0 | AJ14: 1
A15: ='Apr24'!A15+'Apr24'!AI15+'Apr24'!AJ15-'Apr24'!AH15 -> 48 | B15: =Jan!B15 -> D Pangi | AH15: =COUNTIF(C15:AG15, "CO") -> 0 | AI15: =COUNTIF(C15:AG15, "E") -> 0 | AJ15: 1
C16: Legend: CO- CO AVAILED, E-EXTRA DUTY

Sheet jUN24
B1: Attendance Tracker | AE1: June 2024
A4: CF Balance | B4: Name | C4: 1 | D4: 2 | E4: 3 | F4: 4 | G4: 5 | H4: 6 | I4: 7 | J4: 8 | K4: 9 | L4: 10 | M4: 11 | N4: 12 | O4: 13 | P4: 14 | Q4: 15 | R4: 16 | S4: 17 | T4: 18 | U4: 19 | V4: 20 | W4: 21 | X4: 22 | Y4: 23 | Z4: 24 | AA4: 25 | AB4: 26 | AC4: 27 | AD4: 28 | AE4: 29 | AF4: 30 | AH4: CO Availed this month | AI4: Extra Working days this month | AJ4: Addition this month
C5: SAT | D5: SUN | E5: MON | F5: TUE | G5: WED | H5: THU | I5: FRI | J5: SAT | K5: SUN | L5: MON | M5: TUE | N5: WED | O5: THU | P5: FRI | Q5: SAT | R5: SUN | S5: MON | T5: TUE | U5: WED | V5: THU | W5: FRI | X5: SAT | Y5: SUN | Z5: MON | AA5: TUE | AB5: WED | AC5: THU | AD5: FRI | AE5: SAT | AF5: SUN
A6: ='mAY24'!A6+'mAY24'!AI6+'mAY24'!AJ6-'mAY24'!AH6 -> 8 | B6: =Jan!B6 -> KC Tirkey | D6: E | H6: CO | I6: CO | R6: CO | T6: CO | U6: CO | V6: CO | W6: CO | AE6: E | AH6: =COUNTIF(C6:AG6, "CO") -> 7 | AI6: =COUNTIF(C6:AG6, "E") -> 2 | AJ6: 1
A7: ='mAY24'!A7+'mAY24'!AI7+'mAY24'!AJ7-'mAY24'!AH7 -> 21 | B7: =Jan!B7 -> GN Madhei | AD7: E | AE7: CO | AH7: =COUNTIF(C7:AG7, "CO") -> 1 | AI7: =COUNTIF(C7:AG7, "E") -> 1 | AJ7: 1
A8: ='mAY24'!A8+'mAY24'!AI8+'mAY24'!AJ8-'mAY24'!AH8 -> 70 | B8: =Jan!B18 -> S K Sahoo | C8: CO | D8: CO | J8: E | X8: CO | AF8: CO | AH8: =COUNTIF(C8:AG8, "CO") -> 4 | AI8: =COUNTIF(C8:AG8, "E") -> 1 | AJ8: 1
A9: ='mAY24'!A9+'mAY24'!AI9+'mAY24'!AJ9-'mAY24'!AH9 -> 57 | B9: =Jan!B9 -> S Lakra | K9: CO | N9: CO | O9: CO | P9: CO | Q9: CO | AD9: CO | AE9: CO | AH9: =COUNTIF(C9:AG9, "CO") -> 7 | AI9: =COUNTIF(C9:AG9, "E") -> 0 | AJ9: 1
A10: ='mAY24'!A10+'mAY24'!AI10+'mAY24'!AJ10-'mAY24'!AH10 -> 42 | B10: =Jan!B10 -> SK Maharana | N10: CO | O10: CO | AH10: =COUNTIF(C10:AG10, "CO") -> 2 | AI10: =COUNTIF(C10:AG10, "E") -> 0 | AJ10: 1
A11: ='mAY24'!A11+'mAY24'!AI11+'mAY24'!AJ11-'mAY24'!AH11 -> 23 | B11: =Jan!B19 -> A K Dalai | M11: E | O11: E | AD11: CO | AH11: =COUNTIF(C11:AG11, "CO") -> 1 | AI11: =COUNTIF(C11:AG11, "E") -> 2 | AJ11: 1
A12: ='mAY24'!A12+'mAY24'!AI12+'mAY24'!AJ12-'mAY24'!AH12 -> 56 | B12: =Jan!B12 -> RK Singh | AD12: co | AH12: =COUNTIF(C12:AG12, "CO") -> 1 | AI12: =COUNTIF(C12:AG12, "E") -> 0 | AJ12: 1
A13: ='mAY24'!A13+'mAY24'!AI13+'mAY24'!AJ13-'mAY24'!AH13 -> 53 | B13: =Jan!B16 -> M Bishi | AH13: =COUNTIF(C13:AG13, "CO") -> 0 | AI13: =COUNTIF(C13:AG13, "E") -> 0 | AJ13: 1
A14: ='mAY24'!A14+'mAY24'!AI14+'mAY24'!AJ14-'mAY24'!AH14 -> 14 | B14: =Jan!B17 -> S C Behera | F14: CO | AH14: =COUNTIF(C14:AG14, "CO") -> 1 | AI14: =COUNTIF(C14:AG14, "E") -> 0 | AJ14: 1
A15: ='mAY24'!A15+'mAY24'!AI15+'mAY24'!AJ15-'mAY24'!AH15 -> 49 | B15: =Jan!B15 -> D Pangi | G15: CO | H15: CO | I15: CO | J15: CO | AH15: =COUNTIF(C15:AG15, "CO") -> 4 | AI15: =COUNTIF(C15:AG15, "E") -> 0 | AJ15: 1
C16: Legend: CO- CO AVAILED, E-EXTRA DUTY

Sheet jULY24
B1: Attendance Tracker | AE1: July 2024
